Workbook
Name FromOrganiz_1: _xlfn.ANCHORARRAY('Transacciones '!#REF!)
Name SegmentaciónDeDatos_Año: #N/A
Name SegmentaciónDeDatos_Año1: #N/A
Name SegmentaciónDeDatos_Causa: #N/A
Name SegmentaciónDeDatos_Ciudad: #N/A
Name SegmentaciónDeDatos_Encargado: #N/A
Name SegmentaciónDeDatos_Mes: #N/A
Name SegmentaciónDeDatos_Mes1: #N/A
Name SegmentaciónDeDatos_Mes2: #N/A
Name SegmentaciónDeDatos_Producto: #N/A
Name SegmentaciónDeDatos_Producto1: #N/A
Name TRABAJADOR: INDIRECT([1]Calculos!$C$12)

Sheet Dashboard

Sheet Transacciones 
A1: ID | B1: Año | C1: Mes | D1: Mes transaccional | E1: Día | F1: Ciudad | G1: Encargado | H1: Cantidad_Vendida | I1: Cantidad_Vendida Final | J1: Producto | K1: Venta | L1: Ganancia | M1: Precio por producto | O1: Mes | P1: Año | Q1: Año formato | R1: Producto | S1: Producto formato | T1: Cantidad final vendida
A2: 10001 | B2: 2020 | C2: Noviembre | D2: =IF(C2="Enero",1,IF(C2="Febrero",2,IF(C2="Marzo",3,IF(C2="Abril",4,IF(C2="Mayo",5,IF(C2="Junio",6,IF(C2="Julio",7,IF(C2="Agosto",8,IF(C2="Septiembre",9,IF(C2="Octubre",10,IF(C2="Noviembre",11,IF(C2="Diciembre",12,"")))))))))))) -> 11 | E2: 8 | F2: Bogotá | G2: Juan Carlos Londoño | H2: 91 | I2: 91 | J2: (D) | K2: 273000 | L2: 182 | M2: =K2/I2 -> 3000 | P2: 21 | Q2: =VALUE("20"&P2) -> 2021 | R2: C | S2: ="("&R2&")" -> (C) | T2: =SUMIFS($I$2:$I$10001,$J$2:$J$10001,S2,$B$2:$B$10001,Q2,$D$2:$D$10001,O2) -> 0 | AH2: {=AVERAGE(_xlfn.XLOOKUP(LARGE(IF(J79=$J$2:$J$10001,IF(DATE(B79,MONTH(C79&1),E79)>=IF(($H$2:$H$10001<>"")*(J79=$J$2:$J$10001),DATE($B$2:$B$10001,MONTH($C$2:$C$10001&1),$E$2:$E$10001),""),DATE($B$2:$B$10001,MONTH($C$2:$C$10001&1),$E$2:$E$10001)+ROW($B$2:$B$10001)/10000,0),0),_xlfn.SEQUENCE(5)),IF(J79=J2:J10001,IF(DATE(B79,MONTH(C79&1),E79)>=IF(($H$2:$H$10001<>"")*(J79=$J$2:$J$10001),DATE($B$2:$B$10001,MONTH($C$2:$C$10001&1),$E$2:$E$10001),""),DATE($B$2:$B$10001,MONTH($C$2:$C$10001&1),$E$2:$E$10001)+ROW($B$2:$B$10001)/10000,0),0),$H$2:$H$10001,,0,1))} -> #VALUE!
A3: 10002 | B3: 2020 | C3: Octubre | D3: =IF(C3="Enero",1,IF(C3="Febrero",2,IF(C3="Marzo",3,IF(C3="Abril",4,IF(C3="Mayo",5,IF(C3="Junio",6,IF(C3="Julio",7,IF(C3="Agosto",8,IF(C3="Septiembre",9,IF(C3="Octubre",10,IF(C3="Noviembre",11,IF(C3="Diciembre",12,"")))))))))))) -> 10 | E3: 4 | F3: Ibagué | G3: {=_xlfn.XLOOKUP(LARGE(IF((F3=$F$2:$F$10001)*(B3+1=$B$2:$B$10001)*(C3=$C$2:$C$10001),DATE($B$2:$B$10001,MONTH($C$2:$C$10001&1),$E$2:$E$10001)," "),1),IF((F3=$F$2:$F$10001)*(B3+1=$B$2:$B$10001)*(C3=$C$2:$C$10001),DATE($B$2:$B$10001,MONTH($C$2:$C$10001&1),$E$2:$E$10001)," "),$G$2:$G$10001,,0,1)} -> Ernesto Pérez | H3: 179 | I3: 179 | J3: (B) | K3: 1253000 | L3: 716 | M3: =K3/I3 -> 7000 | O3: 12 | P3: 20 | Q3: =VALUE("20"&P3) -> 2020 | R3: A | S3: ="("&R3&")" -> (A) | T3: =SUMIFS($I$2:$I$10001,$J$2:$J$10001,S3,$B$2:$B$10001,Q3,$D$2:$D$10001,O3) -> 5765
A4: 10003 | B4: 2020 | C4: Abril | D4: =IF(C4="Enero",1,IF(C4="Febrero",2,IF(C4="Marzo",3,IF(C4="Abril",4,IF(C4="Mayo",5,IF(C4="Junio",6,IF(C4="Julio",7,IF(C4="Agosto",8,IF(C4="Septiembre",9,IF(C4="Octubre",10,IF(C4="Noviembre",11,IF(C4="Diciembre",12,"")))))))))))) -> 4 | E4: 12 | F4: Montería | G4: Ortensia Giraldo | H4: 245 | I4: 245 | J4: (C) | K4: 1837500 | L4: 612.5 | M4: =K4/I4 -> 7500 | O4: 10 | P4: 20 | Q4: =VALUE("20"&P4) -> 2020 | R4: B | S4: ="("&R4&")" -> (B) | T4: =SUMIFS($I$2:$I$10001,$J$2:$J$10001,S4,$B$2:$B$10001,Q4,$D$2:$D$10001,O4) -> 7882.2 | W4: =_xlfn.FORMULATEXT(U2) -> #N/A
A5: 10004 | B5: 2020 | C5: Agosto | D5: =IF(C5="Enero",1,IF(C5="Febrero",2,IF(C5="Marzo",3,IF(C5="Abril",4,IF(C5="Mayo",5,IF(C5="Junio",6,IF(C5="Julio",7,IF(C5="Agosto",8,IF(C5="Septiembre",9,IF(C5="Octubre",10,IF(C5="Noviembre",11,IF(C5="Diciembre",12,"")))))))))))) -> 8 | E5: 17 | F5: Medellín | G5: Patricia Fernandez | H5: 144 | I5: 144 | J5: (B) | K5: 1008000 | L5: 576 | M5: =K5/I5 -> 7000 | O5: 6 | P5: 22 | Q5: =VALUE("20"&P5) -> 2022 | R5: C | S5: ="("&R5&")" -> (C) | T5: =SUMIFS($I$2:$I$10001,$J$2:$J$10001,S5,$B$2:$B$10001,Q5,$D$2:$D$10001,O5) -> 18875
A6: 10005 | B6: 2020 | C6: Diciembre | D6: =IF(C6="Enero",1,IF(C6="Febrero",2,IF(C6="Marzo",3,IF(C6="Abril",4,IF(C6="Mayo",5,IF(C6="Junio",6,IF(C6="Julio",7,IF(C6="Agosto",8,IF(C6="Septiembre",9,IF(C6="Octubre",10,IF(C6="Noviembre",11,IF(C6="Diciembre",12,"")))))))))))) -> 12 | E6: 14 | F6: Popayán | G6: Carolina Navarro | H6: 116 | I6: 116 | J6: (A) | K6: 638000 | L6: 406 | M6: =K6/I6 -> 5500 | O6: 7 | P6: 20 | Q6: =VALUE("20"&P6) -> 2020 | R6: D | S6: ="("&R6&")" -> (D) | T6: =SUMIFS($I$2:$I$10001,$J$2:$J$10001,S6,$B$2:$B$10001,Q6,$D$2:$D$10001,O6) -> 11654 | W6: 44848
A7: 10006 | B7: 2020 | C7: Septiembre | D7: =IF(C7="Enero",1,IF(C7="Febrero",2,IF(C7="Marzo",3,IF(C7="Abril",4,IF(C7="Mayo",5,IF(C7="Junio",6,IF(C7="Julio",7,IF(C7="Agosto",8,IF(C7="Septiembre",9,IF(C7="Octubre",10,IF(C7="Noviembre",11,IF(C7="Diciembre",12,"")))))))))))) -> 9 | E7: 9 | F7: Cali | G7: Marcela Valencia | H7: 59 | I7: 59 | J7: (D) | K7: 177000 | L7: 118 | M7: =K7/I7 -> 3000 | O7: 12 | P7: 20 | Q7: =VALUE("20"&P7) -> 2020 | R7: D | S7: ="("&R7&")" -> (D) | T7: =SUMIFS($I$2:$I$10001,$J$2:$J$10001,S7,$B$2:$B$10001,Q7,$D$2:$D$10001,O7) -> 6074
A8: 10007 | B8: 2020 | C8: Octubre | D8: =IF(C8="Enero",1,IF(C8="Febrero",2,IF(C8="Marzo",3,IF(C8="Abril",4,IF(C8="Mayo",5,IF(C8="Junio",6,IF(C8="Julio",7,IF(C8="Agosto",8,IF(C8="Septiembre",9,IF(C8="Octubre",10,IF(C8="Noviembre",11,IF(C8="Diciembre",12,"")))))))))))) -> 10 | E8: 7 | F8: Medellín | G8: Ortensia Giraldo | H8: 110 | I8: 110 | J8: (A) | K8: 605000 | L8: 385 | M8: =K8/I8 -> 5500 | O8: 11 | P8: 22 | Q8: =VALUE("20"&P8) -> 2022 | R8: D | S8: ="("&R8&")" -> (D) | T8: =SUMIFS($I$2:$I$10001,$J$2:$J$10001,S8,$B$2:$B$10001,Q8,$D$2:$D$10001,O8) -> 5044 | W8: coin
A9: 10008 | B9: 2020 | C9: Septiembre | D9: =IF(C9="Enero",1,IF(C9="Febrero",2,IF(C9="Marzo",3,IF(C9="Abril",4,IF(C9="Mayo",5,IF(C9="Junio",6,IF(C9="Julio",7,IF(C9="Agosto",8,IF(C9="Septiembre",9,IF(C9="Octubre",10,IF(C9="Noviembre",11,IF(C9="Diciembre",12,"")))))))))))) -> 9 | E9: 25 | F9: Neiva | G9: Marcela Valencia | H9: 66 | I9: 66 | J9: (A) | K9: 363000 | L9: 231 | M9: =K9/I9 -> 5500 | O9: 7 | P9: 21 | Q9: =VALUE("20"&P9) -> 2021 | R9: D | S9: ="("&R9&")" -> (D) | T9: =SUMIFS($I$2:$I$10001,$J$2:$J$10001,S9,$B$2:$B$10001,Q9,$D$2:$D$10001,O9) -> 15856
A10: 10009 | B10: 2020 | C10: Enero | D10: =IF(C10="Enero",1,IF(C10="Febrero",2,IF(C10="Marzo",3,IF(C10="Abril",4,IF(C10="Mayo",5,IF(C10="Junio",6,IF(C10="Julio",7,IF(C10="Agosto",8,IF(C10="Septiembre",9,IF(C10="Octubre",10,IF(C10="Noviembre",11,IF(C10="Diciembre",12,"")))))))))))) -> 1 | E10: 17 | F10: Palmira | G10: Ortensia Giraldo | H10: 242 | I10: 242 | J10: (D) | K10: 580800 | L10: 338.8 | M10: =K10/I10 -> 2400 | O10: 5 | P10: 22 | Q10: =VALUE("20"&P10) -> 2022 | R10: D | S10: ="("&R10&")" -> (D) | T10: =SUMIFS($I$2:$I$10001,$J$2:$J$10001,S10,$B$2:$B$10001,Q10,$D$2:$D$10001,O10) -> 5920
A11: 10010 | B11: 2020 | C11: Febrero | D11: =IF(C11="Enero",1,IF(C11="Febrero",2,IF(C11="Marzo",3,IF(C11="Abril",4,IF(C11="Mayo",5,IF(C11="Junio",6,IF(C11="Julio",7,IF(C11="Agosto",8,IF(C11="Septiembre",9,IF(C11="Octubre",10,IF(C11="Noviembre",11,IF(C11="Diciembre",12,"")))))))))))) -> 2 | E11: 4 | F11: Cali | G11: Marcela Valencia | H11: 295 | I11: 295 | J11: (D) | K11: 708000 | L11: 413 | M11: =K11/I11 -> 2400 | O11: 5 | P11: 20 | Q11: =VALUE("20"&P11) -> 2020 | R11: C | S11: ="("&R11&")" -> (C) | T11: =SUMIFS($I$2:$I$10001,$J$2:$J$10001,S11,$B$2:$B$10001,Q11,$D$2:$D$10001,O11) -> 15702
A12: 10011 | B12: 2020 | C12: Mayo | D12: =IF(C12="Enero",1,IF(C12="Febrero",2,IF(C12="Marzo",3,IF(C12="Abril",4,IF(C12="Mayo",5,IF(C12="Junio",6,IF(C12="Julio",7,IF(C12="Agosto",8,IF(C12="Septiembre",9,IF(C12="Octubre",10,IF(C12="Noviembre",11,IF(C12="Diciembre",12,"")))))))))))) -> 5 | E12: 25 | F12: Popayán | G12: Juan Carlos Londoño | H12: 176 | I12: 176 | J12: (B) | K12: 1232000 | L12: 704 | M12: =K12/I12 -> 7000 | O12: 7 | P12: 22 | Q12: =VALUE("20"&P12) -> 2022 | R12: B | S12: ="("&R12&")" -> (B) | T12: =SUMIFS($I$2:$I$10001,$J$2:$J$10001,S12,$B$2:$B$10001,Q12,$D$2:$D$10001,O12) -> 7986
A13: 10012 | B13: 2020 | C13: Febrero | D13: =IF(C13="Enero",1,IF(C13="Febrero",2,IF(C13="Marzo",3,IF(C13="Abril",4,IF(C13="Mayo",5,IF(C13="Junio",6,IF(C13="Julio",7,IF(C13="Agosto",8,IF(C13="Septiembre",9,IF(C13="Octubre",10,IF(C13="Noviembre",11,IF(C13="Diciembre",12,"")))))))))))) -> 2 | E13: 7 | F13: Ibagué | G13: Ortensia Giraldo | H13: 243 | I13: 243 | J13: (D) | K13: 583200 | L13: 340.2 | M13: =K13/I13 -> 2400 | O13: 4 | P13: 20 | Q13: =VALUE("20"&P13) -> 2020 | R13: C | S13: ="("&R13&")" -> (C) | T13: =SUMIFS($I$2:$I$10001,$J$2:$J$10001,S13,$B$2:$B$10001,Q13,$D$2:$D$10001,O13) -> 16791
A14: 10013 | B14: 2020 | C14: Diciembre | D14: =IF(C14="Enero",1,IF(C14="Febrero",2,IF(C14="Marzo",3,IF(C14="Abril",4,IF(C14="Mayo",5,IF(C14="Junio",6,IF(C14="Julio",7,IF(C14="Agosto",8,IF(C14="Septiembre",9,IF(C14="Octubre",10,IF(C14="Noviembre",11,IF(C14="Diciembre",12,"")))))))))))) -> 12 | E14: 24 | F14: Armenia | G14: Carolina Navarro | H14: 92 | I14: 92 | J14: (D) | K14: 276000 | L14: 184 | M14: =K14/I14 -> 3000 | O14: 12 | P14: 21 | Q14: =VALUE("20"&P14) -> 2021 | R14: C | S14: ="("&R14&")" -> (C) | T14: =SUMIFS($I$2:$I$10001,$J$2:$J$10001,S14,$B$2:$B$10001,Q14,$D$2:$D$10001,O14) -> 16223
A15: 10014 | B15: 2020 | C15: Agosto | D15: =IF(C15="Enero",1,IF(C15="Febrero",2,IF(C15="Marzo",3,IF(C15="Abril",4,IF(C15="Mayo",5,IF(C15="Junio",6,IF(C15="Julio",7,IF(C15="Agosto",8,IF(C15="Septiembre",9,IF(C15="Octubre",10,IF(C15="Noviembre",11,IF(C15="Diciembre",12,"")))))))))))) -> 8 | E15: 30 | F15: Villavicencio | G15: Ernesto Pérez | H15: 238 | I15: 238 | J15: (A) | K15: 1023400 | L15: 547.4 | M15: =K15/I15 -> 4300 | O15: 10 | P15: 22 | Q15: =VALUE("20"&P15) -> 2022 | R15: C | S15: ="("&R15&")" -> (C) | T15: =SUMIFS($I$2:$I$10001,$J$2:$J$10001,S15,$B$2:$B$10001,Q15,$D$2:$D$10001,O15) -> 18802
A16: 10015 | B16: 2020 | C16: Septiembre | D16: =IF(C16="Enero",1,IF(C16="Febrero",2,IF(C16="Marzo",3,IF(C16="Abril",4,IF(C16="Mayo",5,IF(C16="Junio",6,IF(C16="Julio",7,IF(C16="Agosto",8,IF(C16="Septiembre",9,IF(C16="Octubre",10,IF(C16="Noviembre",11,IF(C16="Diciembre",12,"")))))))))))) -> 9 | E16: 22 | F16: Popayán | G16: Ernesto Pérez | H16: 223 | I16: 223 | J16: (C) | K16: 1672500 | L16: 557.5 | M16: =K16/I16 -> 7500 | O16: 2 | P16: 20 | Q16: =VALUE("20"&P16) -> 2020 | R16: D | S16: ="("&R16&")" -> (D) | T16: =SUMIFS($I$2:$I$10001,$J$2:$J$10001,S16,$B$2:$B$10001,Q16,$D$2:$D$10001,O16) -> 17682
A17: 10016 | B17: 2020 | C17: Abril | D17: =IF(C17="Enero",1,IF(C17="Febrero",2,IF(C17="Marzo",3,IF(C17="Abril",4,IF(C17="Mayo",5,IF(C17="Junio",6,IF(C17="Julio",7,IF(C17="Agosto",8,IF(C17="Septiembre",9,IF(C17="Octubre",10,IF(C17="Noviembre",11,IF(C17="Diciembre",12,"")))))))))))) -> 4 | E17: 24 | F17: Bogotá | G17: Carolina Navarro | H17: 106 | I17: 106 | J17: (D) | K17: 318000 | L17: 212 | M17: =K17/I17 -> 3000 | O17: 7 | P17: 22 | Q17: =VALUE("20"&P17) -> 2022 | R17: D | S17: ="("&R17&")" -> (D) | T17: =SUMIFS($I$2:$I$10001,$J$2:$J$10001,S17,$B$2:$B$10001,Q17,$D$2:$D$10001,O17) -> 17959
A18: 10017 | B18: 2020 | C18: Enero | D18: =IF(C18="Enero",1,IF(C18="Febrero",2,IF(C18="Marzo",3,IF(C18="Abril",4,IF(C18="Mayo",5,IF(C18="Junio",6,IF(C18="Julio",7,IF(C18="Agosto",8,IF(C18="Septiembre",9,IF(C18="Octubre",10,IF(C18="Noviembre",11,IF(C18="Diciembre",12,"")))))))))))) -> 1 | E18: 15 | F18: Valledupar | G18: Juan Carlos Londoño | H18: 298 | I18: 298 | J18: (A) | K18: 1281400 | L18: 685.4 | M18: =K18/I18 -> 4300 | O18: 1 | P18: 20 | Q18: =VALUE("20"&P18) -> 2020 | R18: B | S18: ="("&R18&")" -> (B) | T18: =SUMIFS($I$2:$I$10001,$J$2:$J$10001,S18,$B$2:$B$10001,Q18,$D$2:$D$10001,O18) -> 8662
A19: 10018 | B19: 2020 | C19: Octubre | D19: =IF(C19="Enero",1,IF(C19="Febrero",2,IF(C19="Marzo",3,IF(C19="Abril",4,IF(C19="Mayo",5,IF(C19="Junio",6,IF(C19="Julio",7,IF(C19="Agosto",8,IF(C19="Septiembre",9,IF(C19="Octubre",10,IF(C19="Noviembre",11,IF(C19="Diciembre",12,"")))))))))))) -> 10 | E19: 30 | F19: Pereira | G19: Carolina Navarro | H19: 278 | I19: 278 | J19: (C) | K19: 2085000 | L19: 695 | M19: =K19/I19 -> 7500 | O19: 3 | P19: 22 | Q19: =VALUE("20"&P19) -> 2022 | R19: D | S19: ="("&R19&")" -> (D) | T19: =SUMIFS($I$2:$I$10001,$J$2:$J$10001,S19,$B$2:$B$10001,Q19,$D$2:$D$10001,O19) -> 5310
A20: 10019 | B20: 2020 | C20: Marzo | D20: =IF(C20="Enero",1,IF(C20="Febrero",2,IF(C20="Marzo",3,IF(C20="Abril",4,IF(C20="Mayo",5,IF(C20="Junio",6,IF(C20="Julio",7,IF(C20="Agosto",8,IF(C20="Septiembre",9,IF(C20="Octubre",10,IF(C20="Noviembre",11,IF(C20="Diciembre",12,"")))))))))))) -> 3 | E20: 6 | F20: Sincelejo | G20: Marcela Valencia | H20: 262 | I20: 262 | J20: (C) | K20: 1965000 | L20: 655 | M20: =K20/I20 -> 7500 | O20: 9 | P20: 21 | Q20: =VALUE("20"&P20) -> 2021 | R20: A | S20: ="("&R20&")" -> (A) | T20: =SUMIFS($I$2:$I$10001,$J$2:$J$10001,S20,$B$2:$B$10001,Q20,$D$2:$D$10001,O20) -> 6330
... A24: 10023 | B24: 2020 | C24: Agosto | D24: =IF(C24="Enero",1,IF(C24="Febrero",2,IF(C24="Marzo",3,IF(C24="Abril",4,IF(C24="Mayo",5,IF(C24="Junio",6,IF(C24="Julio",7,IF(C24="Agosto",8,IF(C24="Septiembre",9,IF(C24="Octubre",10,IF(C24="Noviembre",11,IF(C24="Diciembre",12,"")))))))))))) -> 8 | E24: 6 | F24: Cali | G24: Ortensia Giraldo | H24: 86 | I24: 86 | J24: (B) | K24: 602000 | L24: 344 | M24: =K24/I24 -> 7000 | O24: 12 | P24: 21 | Q24: =VALUE("20"&P24) -> 2021 | R24: B | S24: ="("&R24&")" -> (B) | T24: =SUMIFS($I$2:$I$10001,$J$2:$J$10001,S24,$B$2:$B$10001,Q24,$D$2:$D$10001,O24) -> 7944
A25: 10024 | B25: 2020 | C25: Octubre | D25: =IF(C25="Enero",1,IF(C25="Febrero",2,IF(C25="Marzo",3,IF(C25="Abril",4,IF(C25="Mayo",5,IF(C25="Junio",6,IF(C25="Julio",7,IF(C25="Agosto",8,IF(C25="Septiembre",9,IF(C25="Octubre",10,IF(C25="Noviembre",11,IF(C25="Diciembre",12,"")))))))))))) -> 10 | E25: 4 | F25: Popayán | G25: {=_xlfn.XLOOKUP(LARGE(IF((F25=$F$2:$F$10001)*(B25+1=$B$2:$B$10001)*(C25=$C$2:$C$10001),DATE($B$2:$B$10001,MONTH($C$2:$C$10001&1),$E$2:$E$10001)," "),1),IF((F25=$F$2:$F$10001)*(B25+1=$B$2:$B$10001)*(C25=$C$2:$C$10001),DATE($B$2:$B$10001,MONTH($C$2:$C$10001&1),$E$2:$E$10001)," "),$G$2:$G$10001,,0,1)} -> Carolina Navarro | H25: 142 | I25: 142 | J25: (B) | K25: 994000 | L25: 568 | M25: =K25/I25 -> 7000 | O25: 2 | P25: 21 | Q25: =VALUE("20"&P25) -> 2021 | R25: D | S25: ="("&R25&")" -> (D) | T25: =SUMIFS($I$2:$I$10001,$J$2:$J$10001,S25,$B$2:$B$10001,Q25,$D$2:$D$10001,O25) -> 16235
A26: 10025 | B26: 2020 | C26: Abril | D26: =IF(C26="Enero",1,IF(C26="Febrero",2,IF(C26="Marzo",3,IF(C26="Abril",4,IF(C26="Mayo",5,IF(C26="Junio",6,IF(C26="Julio",7,IF(C26="Agosto",8,IF(C26="Septiembre",9,IF(C26="Octubre",10,IF(C26="Noviembre",11,IF(C26="Diciembre",12,"")))))))))))) -> 4 | E26: 3 | F26: Santa Marta | G26: Carolina Navarro | H26: 208 | I26: 208 | J26: (C) | K26: 1560000 | L26: 520 | M26: =K26/I26 -> 7500 | O26: 9 | P26: 20 | Q26: =VALUE("20"&P26) -> 2020 | R26: B | S26: ="("&R26&")" -> (B) | T26: =SUMIFS($I$2:$I$10001,$J$2:$J$10001,S26,$B$2:$B$10001,Q26,$D$2:$D$10001,O26) -> 8835
A27: 10026 | B27: 2020 | C27: Octubre | D27: =IF(C27="Enero",1,IF(C27="Febrero",2,IF(C27="Marzo",3,IF(C27="Abril",4,IF(C27="Mayo",5,IF(C27="Junio",6,IF(C27="Julio",7,IF(C27="Agosto",8,IF(C27="Septiembre",9,IF(C27="Octubre",10,IF(C27="Noviembre",11,IF(C27="Diciembre",12,"")))))))))))) -> 10 | E27: 30 | F27: Villavicencio | G27: Ortensia Giraldo | H27: 53 | I27: 53 | J27: (D) | K27: 159000 | L27: 106 | M27: =K27/I27 -> 3000 | O27: 4 | P27: 20 | Q27: =VALUE("20"&P27) -> 2020 | R27: D | S27: ="("&R27&")" -> (D) | T27: =SUMIFS($I$2:$I$10001,$J$2:$J$10001,S27,$B$2:$B$10001,Q27,$D$2:$D$10001,O27) -> 6980
A28: 10027 | B28: 2020 | C28: Marzo | D28: =IF(C28="Enero",1,IF(C28="Febrero",2,IF(C28="Marzo",3,IF(C28="Abril",4,IF(C28="Mayo",5,IF(C28="Junio",6,IF(C28="Julio",7,IF(C28="Agosto",8,IF(C28="Septiembre",9,IF(C28="Octubre",10,IF(C28="Noviembre",11,IF(C28="Diciembre",12,"")))))))))))) -> 3 | E28: 11 | F28: Manizales | G28: Marcela Valencia | H28: 115 | I28: 115 | J28: (D) | K28: 345000 | L28: 230 | M28: =K28/I28 -> 3000 | O28: 6 | P28: 20 | Q28: =VALUE("20"&P28) -> 2020 | R28: B | S28: ="("&R28&")" -> (B) | T28: =SUMIFS($I$2:$I$10001,$J$2:$J$10001,S28,$B$2:$B$10001,Q28,$D$2:$D$10001,O28) -> 9145
A29: 10028 | B29: 2020 | C29: Septiembre | D29: =IF(C29="Enero",1,IF(C29="Febrero",2,IF(C29="Marzo",3,IF(C29="Abril",4,IF(C29="Mayo",5,IF(C29="Junio",6,IF(C29="Julio",7,IF(C29="Agosto",8,IF(C29="Septiembre",9,IF(C29="Octubre",10,IF(C29="Noviembre",11,IF(C29="Diciembre",12,"")))))))))))) -> 9 | E29: 4 | F29: Neiva | G29: Ernesto Pérez | H29: 106 | I29: 106 | J29: (A) | K29: 583000 | L29: 371 | M29: =K29/I29 -> 5500 | O29: 2 | P29: 20 | Q29: =VALUE("20"&P29) -> 2020 | R29: C | S29: ="("&R29&")" -> (C) | T29: =SUMIFS($I$2:$I$10001,$J$2:$J$10001,S29,$B$2:$B$10001,Q29,$D$2:$D$10001,O29) -> 5819
A30: 10029 | B30: 2020 | C30: Junio | D30: =IF(C30="Enero",1,IF(C30="Febrero",2,IF(C30="Marzo",3,IF(C30="Abril",4,IF(C30="Mayo",5,IF(C30="Junio",6,IF(C30="Julio",7,IF(C30="Agosto",8,IF(C30="Septiembre",9,IF(C30="Octubre",10,IF(C30="Noviembre",11,IF(C30="Diciembre",12,"")))))))))))) -> 6 | E30: 5 | F30: Armenia | G30: Ortensia Giraldo | H30: 278 | I30: 278 | J30: (C) | K30: 2085000 | L30: 695 | M30: =K30/I30 -> 7500 | O30: 7 | P30: 21 | Q30: =VALUE("20"&P30) -> 2021 | R30: C | S30: ="("&R30&")" -> (C) | T30: =SUMIFS($I$2:$I$10001,$J$2:$J$10001,S30,$B$2:$B$10001,Q30,$D$2:$D$10001,O30) -> 4211
A31: 10030 | B31: 2020 | C31: Enero | D31: =IF(C31="Enero",1,IF(C31="Febrero",2,IF(C31="Marzo",3,IF(C31="Abril",4,IF(C31="Mayo",5,IF(C31="Junio",6,IF(C31="Julio",7,IF(C31="Agosto",8,IF(C31="Septiembre",9,IF(C31="Octubre",10,IF(C31="Noviembre",11,IF(C31="Diciembre",12,"")))))))))))) -> 1 | E31: 18 | F31: Medellín | G31: Ortensia Giraldo | H31: 174 | I31: 174 | J31: (B) | K31: 1218000 | L31: 696 | M31: =K31/I31 -> 7000 | O31: 5 | P31: 21 | Q31: =VALUE("20"&P31) -> 2021 | R31: A | S31: ="("&R31&")" -> (A) | T31: =SUMIFS($I$2:$I$10001,$J$2:$J$10001,S31,$B$2:$B$10001,Q31,$D$2:$D$10001,O31) -> 5942
A32: 10031 | B32: 2020 | C32: Abril | D32: =IF(C32="Enero",1,IF(C32="Febrero",2,IF(C32="Marzo",3,IF(C32="Abril",4,IF(C32="Mayo",5,IF(C32="Junio",6,IF(C32="Julio",7,IF(C32="Agosto",8,IF(C32="Septiembre",9,IF(C32="Octubre",10,IF(C32="Noviembre",11,IF(C32="Diciembre",12,"")))))))))))) -> 4 | E32: 21 | F32: Pasto | G32: Ortensia Giraldo | H32: 114 | I32: 114 | J32: (A) | K32: 627000 | L32: 399 | M32: =K32/I32 -> 5500 | O32: 6 | P32: 21 | Q32: =VALUE("20"&P32) -> 2021 | R32: B | S32: ="("&R32&")" -> (B) | T32: =SUMIFS($I$2:$I$10001,$J$2:$J$10001,S32,$B$2:$B$10001,Q32,$D$2:$D$10001,O32) -> 6971
A33: 10032 | B33: 2020 | C33: Noviembre | D33: =IF(C33="Enero",1,IF(C33="Febrero",2,IF(C33="Marzo",3,IF(C33="Abril",4,IF(C33="Mayo",5,IF(C33="Junio",6,IF(C33="Julio",7,IF(C33="Agosto",8,IF(C33="Septiembre",9,IF(C33="Octubre",10,IF(C33="Noviembre",11,IF(C33="Diciembre",12,"")))))))))))) -> 11 | E33: 13 | F33: Cartagena | G33: Ortensia Giraldo | H33: 134 | I33: 134 | J33: (B) | K33: 938000 | L33: 536 | M33: =K33/I33 -> 7000 | O33: 9 | P33: 21 | Q33: =VALUE("20"&P33) -> 2021 | R33: B | S33: ="("&R33&")" -> (B) | T33: =SUMIFS($I$2:$I$10001,$J$2:$J$10001,S33,$B$2:$B$10001,Q33,$D$2:$D$10001,O33) -> 8147
A34: 10033 | B34: 2020 | C34: Mayo | D34: =IF(C34="Enero",1,IF(C34="Febrero",2,IF(C34="Marzo",3,IF(C34="Abril",4,IF(C34="Mayo",5,IF(C34="Junio",6,IF(C34="Julio",7,IF(C34="Agosto",8,IF(C34="Septiembre",9,IF(C34="Octubre",10,IF(C34="Noviembre",11,IF(C34="Diciembre",12,"")))))))))))) -> 5 | E34: 19 | F34: Valledupar | G34: Marcela Valencia | H34: 61 | I34: 61 | J34: (D) | K34: 183000 | L34: 122 | M34: =K34/I34 -> 3000 | O34: 1 | P34: 22 | Q34: =VALUE("20"&P34) -> 2022 | R34: C | S34: ="("&R34&")" -> (C) | T34: =SUMIFS($I$2:$I$10001,$J$2:$J$10001,S34,$B$2:$B$10001,Q34,$D$2:$D$10001,O34) -> 6697
A35: 10034 | B35: 2020 | C35: Junio | D35: =IF(C35="Enero",1,IF(C35="Febrero",2,IF(C35="Marzo",3,IF(C35="Abril",4,IF(C35="Mayo",5,IF(C35="Junio",6,IF(C35="Julio",7,IF(C35="Agosto",8,IF(C35="Septiembre",9,IF(C35="Octubre",10,IF(C35="Noviembre",11,IF(C35="Diciembre",12,"")))))))))))) -> 6 | E35: 20 | F35: Montería | G35: Ernesto Pérez | H35: 61 | I35: 61 | J35: (A) | K35: 335500 | L35: 213.5 | M35: =K35/I35 -> 5500 | O35: 7 | P35: 21 | Q35: =VALUE("20"&P35) -> 2021 | R35: B | S35: ="("&R35&")" -> (B) | T35: =SUMIFS($I$2:$I$10001,$J$2:$J$10001,S35,$B$2:$B$10001,Q35,$D$2:$D$10001,O35) -> 6752
A36: 10035 | B36: 2020 | C36: Febrero | D36: =IF(C36="Enero",1,IF(C36="Febrero",2,IF(C36="Marzo",3,IF(C36="Abril",4,IF(C36="Mayo",5,IF(C36="Junio",6,IF(C36="Julio",7,IF(C36="Agosto",8,IF(C36="Septiembre",9,IF(C36="Octubre",10,IF(C36="Noviembre",11,IF(C36="Diciembre",12,"")))))))))))) -> 2 | E36: 1 | F36: Sincelejo | G36: Juan Carlos Londoño | H36: 170 | I36: 170 | J36: (B) | K36: 1190000 | L36: 680 | M36: =K36/I36 -> 7000 | O36: 5 | P36: 22 | Q36: =VALUE("20"&P36) -> 2022 | R36: C | S36: ="("&R36&")" -> (C) | T36: =SUMIFS($I$2:$I$10001,$J$2:$J$10001,S36,$B$2:$B$10001,Q36,$D$2:$D$10001,O36) -> 19451
A37: 10036 | B37: 2020 | C37: Diciembre | D37: =IF(C37="Enero",1,IF(C37="Febrero",2,IF(C37="Marzo",3,IF(C37="Abril",4,IF(C37="Mayo",5,IF(C37="Junio",6,IF(C37="Julio",7,IF(C37="Agosto",8,IF(C37="Septiembre",9,IF(C37="Octubre",10,IF(C37="Noviembre",11,IF(C37="Diciembre",12,"")))))))))))) -> 12 | E37: 25 | F37: Cali | G37: Ortensia Giraldo | H37: 164 | I37: 164 | J37: (B) | K37: 1148000 | L37: 656 | M37: =K37/I37 -> 7000 | O37: 8 | P37: 20 | Q37: =VALUE("20"&P37) -> 2020 | R37: A | S37: ="("&R37&")" -> (A) | T37: =SUMIFS($I$2:$I$10001,$J$2:$J$10001,S37,$B$2:$B$10001,Q37,$D$2:$D$10001,O37) -> #VALUE!
... A56: 10055 | B56: 2020 | C56: Abril | D56: =IF(C56="Enero",1,IF(C56="Febrero",2,IF(C56="Marzo",3,IF(C56="Abril",4,IF(C56="Mayo",5,IF(C56="Junio",6,IF(C56="Julio",7,IF(C56="Agosto",8,IF(C56="Septiembre",9,IF(C56="Octubre",10,IF(C56="Noviembre",11,IF(C56="Diciembre",12,"")))))))))))) -> 4 | E56: 14 | F56: Santa Marta | G56: Carolina Navarro | H56: 229 | I56: 229 | J56: (C) | K56: 1717500 | L56: 572.5 | M56: =K56/I56 -> 7500 | O56: 11 | P56: 20 | Q56: =VALUE("20"&P56) -> 2020 | R56: A | S56: ="("&R56&")" -> (A) | T56: =SUMIFS($I$2:$I$10001,$J$2:$J$10001,S56,$B$2:$B$10001,Q56,$D$2:$D$10001,O56) -> #VALUE!
A57: 10056 | B57: 2020 | C57: Enero | D57: =IF(C57="Enero",1,IF(C57="Febrero",2,IF(C57="Marzo",3,IF(C57="Abril",4,IF(C57="Mayo",5,IF(C57="Junio",6,IF(C57="Julio",7,IF(C57="Agosto",8,IF(C57="Septiembre",9,IF(C57="Octubre",10,IF(C57="Noviembre",11,IF(C57="Diciembre",12,"")))))))))))) -> 1 | E57: 4 | F57: Manizales | G57: {=_xlfn.XLOOKUP(LARGE(IF((F57=$F$2:$F$10001)*(B57+1=$B$2:$B$10001)*(C57=$C$2:$C$10001),DATE($B$2:$B$10001,MONTH($C$2:$C$10001&1),$E$2:$E$10001)," "),1),IF((F57=$F$2:$F$10001)*(B57+1=$B$2:$B$10001)*(C57=$C$2:$C$10001),DATE($B$2:$B$10001,MONTH($C$2:$C$10001&1),$E$2:$E$10001)," "),$G$2:$G$10001,,0,1)} -> Patricia Fernandez | H57: 229 | I57: 229 | J57: (A) | K57: 984700 | L57: 526.7 | M57: =K57/I57 -> 4300 | O57: 12 | P57: 22 | Q57: =VALUE("20"&P57) -> 2022 | R57: D | S57: ="("&R57&")" -> (D) | T57: =SUMIFS($I$2:$I$10001,$J$2:$J$10001,S57,$B$2:$B$10001,Q57,$D$2:$D$10001,O57) -> 5583
A58: 10057 | B58: 2020 | C58: Octubre | D58: =IF(C58="Enero",1,IF(C58="Febrero",2,IF(C58="Marzo",3,IF(C58="Abril",4,IF(C58="Mayo",5,IF(C58="Junio",6,IF(C58="Julio",7,IF(C58="Agosto",8,IF(C58="Septiembre",9,IF(C58="Octubre",10,IF(C58="Noviembre",11,IF(C58="Diciembre",12,"")))))))))))) -> 10 | E58: 20 | F58: Neiva | G58: Patricia Fernandez | H58: 152 | I58: 152 | J58: (B) | K58: 1064000 | L58: 608 | M58: =K58/I58 -> 7000 | O58: 12 | P58: 20 | Q58: =VALUE("20"&P58) -> 2020 | R58: C | S58: ="("&R58&")" -> (C) | T58: =SUMIFS($I$2:$I$10001,$J$2:$J$10001,S58,$B$2:$B$10001,Q58,$D$2:$D$10001,O58) -> 15800
A59: 10058 | B59: 2020 | C59: Julio | D59: =IF(C59="Enero",1,IF(C59="Febrero",2,IF(C59="Marzo",3,IF(C59="Abril",4,IF(C59="Mayo",5,IF(C59="Junio",6,IF(C59="Julio",7,IF(C59="Agosto",8,IF(C59="Septiembre",9,IF(C59="Octubre",10,IF(C59="Noviembre",11,IF(C59="Diciembre",12,"")))))))))))) -> 7 | E59: 28 | F59: Santa Marta | G59: Ortensia Giraldo | H59: 93 | I59: 93 | J59: (C) | K59: 818400 | L59: 353.4 | M59: =K59/I59 -> 8800 | O59: 10 | P59: 20 | Q59: =VALUE("20"&P59) -> 2020 | R59: D | S59: ="("&R59&")" -> (D) | T59: =SUMIFS($I$2:$I$10001,$J$2:$J$10001,S59,$B$2:$B$10001,Q59,$D$2:$D$10001,O59) -> 5339.2
A60: 10059 | B60: 2020 | C60: Septiembre | D60: =IF(C60="Enero",1,IF(C60="Febrero",2,IF(C60="Marzo",3,IF(C60="Abril",4,IF(C60="Mayo",5,IF(C60="Junio",6,IF(C60="Julio",7,IF(C60="Agosto",8,IF(C60="Septiembre",9,IF(C60="Octubre",10,IF(C60="Noviembre",11,IF(C60="Diciembre",12,"")))))))))))) -> 9 | E60: 5 | F60: Pasto | G60: Patricia Fernandez | H60: 73 | I60: 73 | J60: (D) | K60: 219000 | L60: 146 | M60: =K60/I60 -> 3000 | O60: 11 | P60: 22 | Q60: =VALUE("20"&P60) -> 2022 | R60: A | S60: ="("&R60&")" -> (A) | T60: =SUMIFS($I$2:$I$10001,$J$2:$J$10001,S60,$B$2:$B$10001,Q60,$D$2:$D$10001,O60) -> 6034
A61: 10060 | B61: 2020 | C61: Agosto | D61: =IF(C61="Enero",1,IF(C61="Febrero",2,IF(C61="Marzo",3,IF(C61="Abril",4,IF(C61="Mayo",5,IF(C61="Junio",6,IF(C61="Julio",7,IF(C61="Agosto",8,IF(C61="Septiembre",9,IF(C61="Octubre",10,IF(C61="Noviembre",11,IF(C61="Diciembre",12,"")))))))))))) -> 8 | E61: 4 | F61: Santa Marta | G61: Juan Carlos Londoño | H61: 267 | I61: 267 | J61: (A) | K61: 1148100 | L61: 614.1 | M61: =K61/I61 -> 4300 | O61: 2 | P61: 22 | Q61: =VALUE("20"&P61) -> 2022 | R61: A | S61: ="("&R61&")" -> (A) | T61: =SUMIFS($I$2:$I$10001,$J$2:$J$10001,S61,$B$2:$B$10001,Q61,$D$2:$D$10001,O61) -> 16265
...

Sheet Operacional
A1: Mes | B1: Año | C1: Producto | D1: Producción | E1: Pérdidas | F1: Causa | G1: ='Transacciones '!T1 -> Cantidad final vendida | H1: Perdida desconocida | I1: Proporción de Producto Perdido Desconocido
A2: 11 | B2: 21 | C2: C | D2: 23300 | E2: 4334 | F2: Plagas | G2: ='Transacciones '!T2 -> 0 | H2: =D2-E2-G2 -> 18966 | I2: =H2/(H2+E2) -> 0.81399142
A3: 12 | B3: 20 | C3: A | D3: 8000 | E3: 1966 | F3: Transporte | G3: ='Transacciones '!T3 -> 5765 | H3: =D3-E3-G3 -> 269 | I3: =H3/(H3+E3) -> 0.12035794
A4: 10 | B4: 20 | C4: B | D4: 9300 | E4: 1240 | F4: Transporte | G4: ='Transacciones '!T4 -> 7882.2 | H4: =D4-E4-G4 -> 177.8 | I4: =H4/(H4+E4) -> 0.12540556
A5: 6 | B5: 22 | C5: C | D5: 23000 | E5: 3423 | F5: Transporte | G5: ='Transacciones '!T5 -> 18875 | H5: =D5-E5-G5 -> 702 | I5: =H5/(H5+E5) -> 0.17018182
A6: 7 | B6: 20 | C6: D | D6: 13300 | E6: 1333 | F6: Transporte | G6: ='Transacciones '!T6 -> 11654 | H6: =D6-E6-G6 -> 313 | I6: =H6/(H6+E6) -> 0.19015796
A7: 12 | B7: 20 | C7: D | D7: 6300 | E7: 198 | F7: Transporte | G7: ='Transacciones '!T7 -> 6074 | H7: =D7-E7-G7 -> 28 | I7: =H7/(H7+E7) -> 0.12389381
A8: 11 | B8: 22 | C8: D | D8: 6000 | E8: 822 | F8: Transporte | G8: ='Transacciones '!T8 -> 5044 | H8: =D8-E8-G8 -> 134 | I8: =H8/(H8+E8) -> 0.14016736
A9: 7 | B9: 21 | C9: D | D9: 17500 | E9: 1249 | F9: Plagas | G9: ='Transacciones '!T9 -> 15856 | H9: =D9-E9-G9 -> 395 | I9: =H9/(H9+E9) -> 0.24026764
A10: 5 | B10: 22 | C10: D | D10: 6000 | E10: 66 | F10: Plagas | G10: ='Transacciones '!T10 -> 5920 | H10: =D10-E10-G10 -> 14 | I10: =H10/(H10+E10) -> 0.175
A11: 5 | B11: 20 | C11: C | D11: 19000 | E11: 2572 | F11: Robo | G11: ='Transacciones '!T11 -> 15702 | H11: =D11-E11-G11 -> 726 | I11: =H11/(H11+E11) -> 0.22013341
A12: 7 | B12: 22 | C12: B | D12: 9400 | E12: 1145 | F12: Transporte | G12: ='Transacciones '!T12 -> 7986 | H12: =D12-E12-G12 -> 269 | I12: =H12/(H12+E12) -> 0.19024045
A13: 4 | B13: 20 | C13: C | D13: 19300 | E13: 1906 | F13: Transporte | G13: ='Transacciones '!T13 -> 16791 | H13: =D13-E13-G13 -> 603 | I13: =H13/(H13+E13) -> 0.24033479
... A145: 6 | B145: 21 | C145: A | D145: 8800 | E145: 2439 | F145: Almacenamiento | G145: ='Transacciones '!T145 -> 5896 | H145: =D145-E145-G145 -> 465 | I145: =H145/(H145+E145) -> 0.16012397

Sheet Cantidad de Ventas por Producto
A3: Suma de Cantidad_Vendida | B3: Años
A4: Productos | B4: 2020 | C4: 2021 | D4: 2022 | E4: Total general
A5: (A) | B5: 19987 | C5: 18542 | D5: 18934 | E5: 57463
A6: (B) | B6: 7487 | C6: 6752 | D6: 7986 | E6: 22225
A7: (C) | B7: 4202 | C7: 4211 | D7: 5905 | E7: 14318
A8: (D) | B8: 11654 | C8: 15856 | D8: 17959 | E8: 45469
A9: Total general | B9: 43330 | C9: 45361 | D9: 50784 | E9: 139475

Sheet Cociente de producción 
A3: Etiquetas de fila | B3: Cociente de Producción por Pérdidas
A4: A | B4: 5.7141449
A5: B | B5: 7.1313465
A6: C | B6: 7.5589675
A7: D | B7: 12.660966

Sheet Top 5 lugares por Ventas
A3: Ciudades | B3: Ventas Totales | C3: Ciudades | D3: Ventas
A4: Valledupar | B4: 43317900 | C4: =IF(A4="Cartagena","Cartagena de Indias",IF((A4="Total general")+(A4= ""),"",A4)) -> Valledupar | D4: =IF(A4="Total general","",IF(B4<>"",B4,"")) -> 43317900
A5: Cartagena | B5: 42390900 | C5: =IF(A5="Cartagena","Cartagena de Indias",IF((A5="Total general")+(A5= ""),"",A5)) -> Cartagena de Indias | D5: =IF(A5="Total general","",IF(B5<>"",B5,"")) -> 42390900
A6: Bogotá | B6: 38110600 | C6: =IF(A6="Cartagena","Cartagena de Indias",IF((A6="Total general")+(A6= ""),"",A6)) -> Bogotá | D6: =IF(A6="Total general","",IF(B6<>"",B6,"")) -> 38110600
A7: Ibagué | B7: 37953400 | C7: =IF(A7="Cartagena","Cartagena de Indias",IF((A7="Total general")+(A7= ""),"",A7)) -> Ibagué | D7: =IF(A7="Total general","",IF(B7<>"",B7,"")) -> 37953400
A8: Pasto | B8: 37298500 | C8: =IF(A8="Cartagena","Cartagena de Indias",IF((A8="Total general")+(A8= ""),"",A8)) -> Pasto | D8: =IF(A8="Total general","",IF(B8<>"",B8,"")) -> 37298500
A9: Total general | B9: 199071300 | C9: =IF(A9="Cartagena","Cartagena de Indias",IF((A9="Total general")+(A9= ""),"",A9)) | D9: =IF(A9="Total general","",IF(B9<>"",B9,""))
C10: =IF(A10="Cartagena","Cartagena de Indias",IF((A10="Total general")+(A10= ""),"",A10)) | D10: =IF(A10="Total general","",IF(B10<>"",B10,""))
C11: =IF(A11="Cartagena","Cartagena de Indias",IF((A11="Total general")+(A11= ""),"",A11)) | D11: =IF(A11="Total general","",IF(B11<>"",B11,""))
C12: =IF(A12="Cartagena","Cartagena de Indias",IF((A12="Total general")+(A12= ""),"",A12)) | D12: =IF(A12="Total general","",IF(B12<>"",B12,""))
C13: =IF(A13="Cartagena","Cartagena de Indias",IF((A13="Total general")+(A13= ""),"",A13)) | D13: =IF(A13="Total general","",IF(B13<>"",B13,""))
C14: =IF(A14="Cartagena","Cartagena de Indias",IF((A14="Total general")+(A14= ""),"",A14)) | D14: =IF(A14="Total general","",IF(B14<>"",B14,""))
C15: =IF(A15="Cartagena","Cartagena de Indias",IF((A15="Total general")+(A15= ""),"",A15))
C16: =IF(A16="Cartagena","Cartagena de Indias",IF((A16="Total general")+(A16= ""),"",A16)) | D16: =IF(A16="Total general","",IF(B16<>"",B16,""))
C17: =IF(A17="Cartagena","Cartagena de Indias",IF((A17="Total general")+(A17= ""),"",A17)) | D17: =IF(A17="Total general","",IF(B17<>"",B17,""))
C18: =IF(A18="Cartagena","Cartagena de Indias",IF((A18="Total general")+(A18= ""),"",A18)) | D18: =IF(A18="Total general","",IF(B18<>"",B18,""))
C19: =IF(A19="Cartagena","Cartagena de Indias",IF((A19="Total general")+(A19= ""),"",A19)) | D19: =IF(A19="Total general","",IF(B19<>"",B19,""))
C20: =IF(A20="Cartagena","Cartagena de Indias",IF((A20="Total general")+(A20= ""),"",A20)) | D20: =IF(A20="Total general","",IF(B20<>"",B20,""))
C21: =IF(A21="Cartagena","Cartagena de Indias",IF((A21="Total general")+(A21= ""),"",A21))
C22: =IF(A22="Cartagena","Cartagena de Indias",IF((A22="Total general")+(A22= ""),"",A22))
C23: =IF(A23="Cartagena","Cartagena de Indias",IF((A23="Total general")+(A23= ""),"",A23))
C24: =IF(A24="Cartagena","Cartagena de Indias",IF((A24="Total general")+(A24= "")," ",A24))
C25: =IF(A25="Cartagena","Cartagena de Indias",IF((A25="Total general")+(A25= "")," ",A25))
C26: =IF(A26="Cartagena","Cartagena de Indias",IF((A26="Total general")+(A26= "")," ",A26))
C27: =IF(A27="Cartagena","Cartagena de Indias",IF((A27="Total general")+(A27= "")," ",A27))
C28: =IF(A28="Cartagena","Cartagena de Indias",IF((A28="Total general")+(A28= "")," ",A28))
D29: =IF(B29<>"",B29,"")

Sheet Fluctuacion de precios
A2: Año | B2: (Todas)
A4: Suma de Precio por producto | B4: Producto
A5: Mes | B5: (A) | C5: (B) | D5: (C) | E5: (D) | F5: Total general
A6: Enero | B6: 967500 | C6: 1701000 | D6: 1883200 | E6: 528000 | F6: 5079700
A7: Febrero | B7: 881604.26 | C7: 1330000 | D7: 1777600 | E7: 492000 | F7: 4481204.3
A8: Marzo | B8: 1210000 | C8: 1596000 | D8: 1597500 | E8: 579000 | F8: 4982500
A9: Abril | B9: 1201490.8 | C9: 1407000 | D9: 1605000 | E9: 642000 | F9: 4855490.8
A10: Mayo | B10: 1270500 | C10: 1526000 | D10: 1440000 | E10: 651000 | F10: 4887500
A11: Junio | B11: 1083500 | C11: 1449000 | D11: 1590000 | E11: 549000 | F11: 4671500
A12: Julio | B12: 984700 | C12: 1365000 | D12: 1531200 | E12: 441600 | F12: 4322500
A13: Agosto | B13: 876681.09 | C13: 1428000 | D13: 1962400 | E13: 458400 | F13: 4725481.1
A14: Septiembre | B14: 1176682.2 | C14: 1463000 | D14: 1624600.7 | E14: 581770.27 | F14: 4846053.1
A15: Octubre | B15: 1122000 | C15: 1377636.1 | D15: 1545000 | E15: 594411.21 | F15: 4639047.3
A16: Noviembre | B16: 1202287.9 | C16: 1456000 | D16: 1567500 | E16: 633000 | F16: 4858787.9
A17: Diciembre | B17: 1182500 | C17: 1493737.4 | D17: 1575000 | E17: 633000 | F17: 4884237.4
A18: Total general | B18: 13159446 | C18: 17592373 | D18: 19699001 | E18: 6783181.5 | F18: 57234002

Sheet Proporción de producto perdido 
A1: Producto | B1: Suma de Pérdidas conocidas | C1: Perdida desconocida | D1: Proporción de Producto Perdido Desconocido
A2: A | B2: 81167 | C2: 21934.4 | D2: 7.3304924
A3: B | B3: 49023 | C3: 12680 | D3: 7.3431074
A4: C | B4: 77246 | C4: 19978.4 | D4: 7.4857677
A5: D | B5: 29587 | C5: 7511 | D5: 7.2922832
A6: Total general | B6: 237023 | C6: 62103.8 | D6: 29.451651
A12: Año | B12: (Todas)
A13: Mes | B13: (Todas)
A15: Producto | B15: Proporción de Producto Perdido Desconocido
A16: A | B16: 7.3304924
A17: B | B17: 7.3431074
A18: C | B18: 7.4857677
A19: D | B19: 7.2922832
A20: Total general | B20: 29.451651

Sheet Análisis de ventas por gerente
A2: Suma de Venta | B2: Producto
A3: Encargado | B3: (A) | C3: (B) | D3: (C) | E3: (D) | F3: Total general
A4: Carolina Navarro | B4: 291658300 | C4: 353185000 | D4: 649178000 | E4: 131244000 | F4: 1425265300
A5: Ernesto Pérez | B5: 278989800 | C5: 327887000 | D5: 580264100 | E5: 141466200 | F5: 1328607100
A6: Juan Carlos Londoño | B6: 307100100 | C6: 343896000 | D6: 606706300 | E6: 157116000 | F6: 1414818400
A7: Marcela Valencia | B7: 292443200 | C7: 328090000 | D7: 632283400 | E7: 159264600 | F7: 1412081200
A8: Ortensia Giraldo | B8: 299999100 | C8: 310191000 | D8: 625975400 | E8: 146810400 | F8: 1382975900
A9: Patricia Fernandez | B9: 255625000 | C9: 352142000 | D9: 644294900 | E9: 156854400 | F9: 1408916300
A10: Total general | B10: 1725815500 | C10: 2015391000 | D10: 3738702100 | E10: 892755600 | F10: 8372664200
A23: Cuenta de Cantidad_Vendida Final | B23: Producto
A24: Encargado | B24: (A) | C24: (B) | D24: (C) | E24: (D) | F24: Total general
A25: Carolina Navarro | B25: 430 | C25: 438 | D25: 418 | E25: 352 | F25: 1638
A26: Ernesto Pérez | B26: 423 | C26: 414 | D26: 391 | E26: 390 | F26: 1618
A27: Juan Carlos Londoño | B27: 461 | C27: 431 | D27: 407 | E27: 420 | F27: 1719
A28: Marcela Valencia | B28: 440 | C28: 403 | D28: 418 | E28: 445 | F28: 1706
A29: Ortensia Giraldo | B29: 442 | C29: 394 | D29: 420 | E29: 389 | F29: 1645
A30: Patricia Fernandez | B30: 384 | C30: 433 | D30: 432 | E30: 425 | F30: 1674
A31: Total general | B31: 2580 | C31: 2513 | D31: 2486 | E31: 2421 | F31: 10000

Sheet Temporada de lluvias vs perdida
A5: Suma de Pérdidas | B5: Etiquetas de columna
A6: Etiquetas de fila | B6: A | C6: B | D6: C | E6: D | F6: Total general
A7: 2020 | B7: 28370 | C7: 16031 | D7: 23488 | E7: 9344 | F7: 77233
A8: Temporada seca | B8: 14558 | C8: 5033 | D8: 4963 | E8: 5046 | F8: 29600
A9: Temporada lluvia | B9: 13812 | C9: 10998 | D9: 18525 | E9: 4298 | F9: 47633
A10: 2021 | B10: 25190 | C10: 17005 | D10: 28239 | E10: 10019 | F10: 80453
A11: Temporada seca | B11: 12094 | C11: 6674 | D11: 4060 | E11: 6487 | F11: 29315
A12: Temporada lluvia | B12: 13096 | C12: 10331 | D12: 24179 | E12: 3532 | F12: 51138
A13: 2022 | B13: 27607 | C13: 15987 | D13: 25519 | E13: 10224 | F13: 79337
A14: Temporada seca | B14: 16193 | C14: 5264 | D14: 5479 | E14: 6585 | F14: 33521
A15: Temporada lluvia | B15: 11414 | C15: 10723 | D15: 20040 | E15: 3639 | F15: 45816
A16: Total general | B16: 81167 | C16: 49023 | D16: 77246 | E16: 29587 | F16: 237023

Sheet Perdidas de producto por causas
A1: Mes | B1: (Todas)
A2: Año | B2: (Todas)
A4: Suma de Pérdidas | B4: Causas de pérdidas
A5: Producto | B5: Almacenamiento | C5: Baja demanda | D5: Clima | E5: Plagas | F5: Robo | G5: Transporte | H5: Total general
A6: A | B6: 17846 | C6: 5930 | D6: 8552 | E6: 16125 | F6: 10097 | G6: 22617 | H6: 81167
A7: B | B7: 4066 | C7: 6244 | D7: 8329 | E7: 14875 | F7: 5003 | G7: 10506 | H7: 49023
A8: C | B8: 13507 | C8: 7153 | D8: 10895 | E8: 8599 | F8: 21683 | G8: 15409 | H8: 77246
A9: D | B9: 2688 | C9: 1328 | D9: 7805 | E9: 6547 | F9: 2475 | G9: 8744 | H9: 29587
A10: Total general | B10: 38107 | C10: 20655 | D10: 35581 | E10: 46146 | F10: 39258 | G10: 57276 | H10: 237023

Sheet Productos más Vendidos por ciud
A3: Ventas Totales | B3: Ciudades
A4: Productos | B4: (A) | C4: (B) | D4: (C) | E4: (D) | F4: Total general
A5: Armenia | B5: 10930600 | C5: 9359000 | D5: 2965600 | E5: 5767200 | F5: 29022400
A6: Barranquilla | B6: 5641600 | C6: 9828000 | D6: 3740000 | E6: 6064800 | F6: 25274400
A7: Bogotá | B7: 17604200 | C7: 6412000 | D7: 6582400 | E7: 7512000 | F7: 38110600
A8: Bucaramanga | B8: 5125600 | C8: 6951000 | D8: 7233600 | E8: 2740800 | F8: 22051000
A9: Cali | B9: 11352000 | C9: 5299000 | D9: 4831200 | E9: 6583200 | F9: 28065400
A10: Cartagena | B10: 16653900 | C10: 9821000 | D10: 10436800 | E10: 5479200 | F10: 42390900
A11: Cúcuta | B11: 11270300 | C11: 6216000 | D11: 6212800 | E11: 3422400 | F11: 27121500
A12: Ibagué | B12: 11919600 | C12: 11613000 | D12: 8192800 | E12: 6228000 | F12: 37953400
A13: Manizales | B13: 12930100 | C13: 9793000 | D13: 5385600 | E13: 6597600 | F13: 34706300
A14: Medellín | B14: 6579000 | C14: 7504000 | D14: 4417600 | E14: 4063200 | F14: 22563800
A15: Montería | B15: 16142200 | C15: 6615000 | D15: 10762400 | E15: 3007200 | F15: 36526800
A16: Neiva | B16: 20769000 | C16: 6566000 | D16: 4100800 | E16: 4228800 | F16: 35664600
... A25: Total general | B25: 247090900 | C25: 155575000 | D25: 125998400 | E25: 109125600 | F25: 637789900
