Workbook
Name Gráfico: CHOOSE(#REF!,rango1,rango2)
Name rango1: #REF!
Name rango2: #REF!
Name SegmentaciónDeDatos_Estado: #N/A

Sheet Datos Introducción
A1: Fecha | B1: Prod/Serv | C1: Tipo | D1: Precio [COP] | E1: Mecánico | F1: Tiempo [min] | G1: Propina [COP] | H1: Calificación
A2: 43646 | B2: alineación | C2: servicio | D2: 30000 | E2: Laura | F2: 39 | G2: 1100 | H2: 5 | I2: =MONTH(A2) -> 6
A3: 43690 | B3: balanceo | C3: servicio | D3: 25000 | E3: Pepe | F3: 54 | G3: 3700 | H3: 10
A4: 43658 | B4: aceite2 | C4: producto | D4: 30000 | E4: Juan | F4: 6 | G4: 2600 | H4: 9
A5: 43481 | B5: gasolina3 | C5: producto | D5: 13000 | E5: María | F5: 8 | G5: 400 | H5: 8
A6: 43778 | B6: cambio llantas | C6: servicio | D6: 10000 | E6: Pepe | F6: 148 | G6: 1000 | H6: 9
A7: 43609 | B7: aceite2 | C7: producto | D7: 30000 | E7: Juan | F7: 6 | G7: 4100 | H7: 10
A8: 43499 | B8: aceite2 | C8: producto | D8: 30000 | E8: Laura | F8: 5 | G8: 1300 | H8: 8
A9: 43743 | B9: balanceo | C9: servicio | D9: 25000 | E9: María | F9: 51 | G9: 800 | H9: 8
A10: 43469 | B10: cambio aceite | C10: servicio | D10: 35000 | E10: Laura | F10: 213 | G10: 3300 | H10: 7
A11: 43777 | B11: alineación | C11: servicio | D11: 30000 | E11: Laura | F11: 40 | G11: 1200 | H11: 8
A12: 43701 | B12: cambio aceite | C12: servicio | D12: 35000 | E12: Laura | F12: 188 | G12: 1500 | H12: 4
A13: 43783 | B13: balanceo | C13: servicio | D13: 25000 | E13: Laura | F13: 48 | G13: 700 | H13: 7
A14: 43513 | B14: aceite1 | C14: producto | D14: 40000 | E14: Juan | F14: 6 | G14: 3200 | H14: 10
... A585: 43600 | B585: llantas | C585: producto | D585: 125000 | E585: Laura | F585: 53 | G585: 5400 | H585: 6

Sheet Introducción
A1: Para realizar gráficos se debe tener primero los datos
A3: Columnas | F3: 1. Obtenga los datos necesarios (total propinas año y calificación promedio).
F4: 2. Realice un gráfico de barras del total de propinas anuales para cada mecánico.
B5: Mecánico | C5: Total propinas | D5: Calificación Prom Oper | F5: 3. En el mismo gráfico adicione la serie de calificación promedio | M5: mi tiru
B6: Laura | C6: =SUMIF('Datos Introducción'!$E$2:$E$585,Introducción!B6,'Datos Introducción'!G2:G585) -> 308100 | D6: =AVERAGEIF('Datos Introducción'!$E$2:$E$585,Introducción!B6,'Datos Introducción'!$H$2:$H$585) -> 5.1472868 | F6: 4. Agrege un nuevo eje, títulos y juegue con los colores.
B7: Pepe | C7: =SUMIF('Datos Introducción'!$E$2:$E$585,Introducción!B7,'Datos Introducción'!G3:G586) -> 314800 | D7: =AVERAGEIF('Datos Introducción'!$E$2:$E$585,Introducción!B7,'Datos Introducción'!$H$2:$H$585) -> 4.7744361 | F7: 5. Títulos desde celdas
B8: Juan | C8: =SUMIF('Datos Introducción'!$E$2:$E$585,Introducción!B8,'Datos Introducción'!G4:G587) -> 343000 | D8: =AVERAGEIF('Datos Introducción'!$E$2:$E$585,Introducción!B8,'Datos Introducción'!$H$2:$H$585) -> 4.8366013
B9: María | C9: =SUMIF('Datos Introducción'!$E$2:$E$585,Introducción!B9,'Datos Introducción'!G5:G588) -> 369000 | D9: =AVERAGEIF('Datos Introducción'!$E$2:$E$585,Introducción!B9,'Datos Introducción'!$H$2:$H$585) -> 5.2485207
A12: Dispersión
B14: Mes | C14: Tiempo Prom [min] | D14: Calificación Prom | E14: Propina Prom [$] | G14: 1. Obtener los datos necesarios
B15: 1 | C15: {=AVERAGE(IF(IF($B15=MONTH('Datos Introducción'!$A$2:$A$585),1,0),'Datos Introducción'!$F$2:$F$585,""))} -> 39.551724 | D15: {=AVERAGE(IF(IF($B15=MONTH('Datos Introducción'!$A$2:$A$585),1,0),'Datos Introducción'!$H$2:$H$585,""))} -> 5.1034483 | E15: {=AVERAGE(IF(IF($B15=MONTH('Datos Introducción'!$A$2:$A$585),1,0),'Datos Introducción'!$G$2:$G$585,""))} -> 2672.4138 | G15: 2. Realice un gráfico de disperción (rectas) mostrando las tres series de datos, use dos ejes verticales
B16: 2 | C16: {=AVERAGE(IF(IF($B16=MONTH('Datos Introducción'!$A$2:$A$585),1,0),'Datos Introducción'!$F$2:$F$585,""))} -> 37 | D16: {=AVERAGE(IF(IF($B16=MONTH('Datos Introducción'!$A$2:$A$585),1,0),'Datos Introducción'!$H$2:$H$585,""))} -> 5.25 | E16: {=AVERAGE(IF(IF($B16=MONTH('Datos Introducción'!$A$2:$A$585),1,0),'Datos Introducción'!$G$2:$G$585,""))} -> 1902.7778 | G16: 3. Use un gráfico combinado
B17: 3 | C17: {=AVERAGE(IF(IF($B17=MONTH('Datos Introducción'!$A$2:$A$585),1,0),'Datos Introducción'!$F$2:$F$585,""))} -> 63.108696 | D17: {=AVERAGE(IF(IF($B17=MONTH('Datos Introducción'!$A$2:$A$585),1,0),'Datos Introducción'!$H$2:$H$585,""))} -> 4.3913043 | E17: {=AVERAGE(IF(IF($B17=MONTH('Datos Introducción'!$A$2:$A$585),1,0),'Datos Introducción'!$G$2:$G$585,""))} -> 2589.1304 | G17: 4. Agregue títulos títulos
B18: 4 | C18: {=AVERAGE(IF(IF($B18=MONTH('Datos Introducción'!$A$2:$A$585),1,0),'Datos Introducción'!$F$2:$F$585,""))} -> 59.465517 | D18: {=AVERAGE(IF(IF($B18=MONTH('Datos Introducción'!$A$2:$A$585),1,0),'Datos Introducción'!$H$2:$H$585,""))} -> 5 | E18: {=AVERAGE(IF(IF($B18=MONTH('Datos Introducción'!$A$2:$A$585),1,0),'Datos Introducción'!$G$2:$G$585,""))} -> 1803.4483 | G18: 5. Probar escala logarítmica
B19: 5 | C19: {=AVERAGE(IF(IF($B19=MONTH('Datos Introducción'!$A$2:$A$585),1,0),'Datos Introducción'!$F$2:$F$585,""))} -> 35.212766 | D19: {=AVERAGE(IF(IF($B19=MONTH('Datos Introducción'!$A$2:$A$585),1,0),'Datos Introducción'!$H$2:$H$585,""))} -> 5.2978723 | E19: {=AVERAGE(IF(IF($B19=MONTH('Datos Introducción'!$A$2:$A$585),1,0),'Datos Introducción'!$G$2:$G$585,""))} -> 2176.5957 | G19: 6. Quitar ceros de las etiquetas del eje
B20: 6 | C20: {=AVERAGE(IF(IF($B20=MONTH('Datos Introducción'!$A$2:$A$585),1,0),'Datos Introducción'!$F$2:$F$585,""))} -> 60.625 | D20: {=AVERAGE(IF(IF($B20=MONTH('Datos Introducción'!$A$2:$A$585),1,0),'Datos Introducción'!$H$2:$H$585,""))} -> 4.8 | E20: {=AVERAGE(IF(IF($B20=MONTH('Datos Introducción'!$A$2:$A$585),1,0),'Datos Introducción'!$G$2:$G$585,""))} -> 2587.5 | G20: ¿Es un buen gráfico?
B21: 7 | C21: {=AVERAGE(IF(IF($B21=MONTH('Datos Introducción'!$A$2:$A$585),1,0),'Datos Introducción'!$F$2:$F$585,""))} -> 33.477273 | D21: {=AVERAGE(IF(IF($B21=MONTH('Datos Introducción'!$A$2:$A$585),1,0),'Datos Introducción'!$H$2:$H$585,""))} -> 4.9772727 | E21: {=AVERAGE(IF(IF($B21=MONTH('Datos Introducción'!$A$2:$A$585),1,0),'Datos Introducción'!$G$2:$G$585,""))} -> 2706.8182
B22: 8 | C22: {=AVERAGE(IF(IF($B22=MONTH('Datos Introducción'!$A$2:$A$585),1,0),'Datos Introducción'!$F$2:$F$585,""))} -> 57.75 | D22: {=AVERAGE(IF(IF($B22=MONTH('Datos Introducción'!$A$2:$A$585),1,0),'Datos Introducción'!$H$2:$H$585,""))} -> 4.8 | E22: {=AVERAGE(IF(IF($B22=MONTH('Datos Introducción'!$A$2:$A$585),1,0),'Datos Introducción'!$G$2:$G$585,""))} -> 2168.3333
B23: 9 | C23: {=AVERAGE(IF(IF($B23=MONTH('Datos Introducción'!$A$2:$A$585),1,0),'Datos Introducción'!$F$2:$F$585,""))} -> 36.511111 | D23: {=AVERAGE(IF(IF($B23=MONTH('Datos Introducción'!$A$2:$A$585),1,0),'Datos Introducción'!$H$2:$H$585,""))} -> 4.6444444 | E23: {=AVERAGE(IF(IF($B23=MONTH('Datos Introducción'!$A$2:$A$585),1,0),'Datos Introducción'!$G$2:$G$585,""))} -> 2060
B24: 10 | C24: {=AVERAGE(IF(IF($B24=MONTH('Datos Introducción'!$A$2:$A$585),1,0),'Datos Introducción'!$F$2:$F$585,""))} -> 47.434783 | D24: {=AVERAGE(IF(IF($B24=MONTH('Datos Introducción'!$A$2:$A$585),1,0),'Datos Introducción'!$H$2:$H$585,""))} -> 5.3043478 | E24: {=AVERAGE(IF(IF($B24=MONTH('Datos Introducción'!$A$2:$A$585),1,0),'Datos Introducción'!$G$2:$G$585,""))} -> 2330.4348
B25: 11 | C25: {=AVERAGE(IF(IF($B25=MONTH('Datos Introducción'!$A$2:$A$585),1,0),'Datos Introducción'!$F$2:$F$585,""))} -> 57.863636 | D25: {=AVERAGE(IF(IF($B25=MONTH('Datos Introducción'!$A$2:$A$585),1,0),'Datos Introducción'!$H$2:$H$585,""))} -> 5.1363636 | E25: {=AVERAGE(IF(IF($B25=MONTH('Datos Introducción'!$A$2:$A$585),1,0),'Datos Introducción'!$G$2:$G$585,""))} -> 3015.9091
B26: 12 | C26: {=AVERAGE(IF(IF($B26=MONTH('Datos Introducción'!$A$2:$A$585),1,0),'Datos Introducción'!$F$2:$F$585,""))} -> 49.733333 | D26: {=AVERAGE(IF(IF($B26=MONTH('Datos Introducción'!$A$2:$A$585),1,0),'Datos Introducción'!$H$2:$H$585,""))} -> 5.3666667 | E26: {=AVERAGE(IF(IF($B26=MONTH('Datos Introducción'!$A$2:$A$585),1,0),'Datos Introducción'!$G$2:$G$585,""))} -> 1900

Sheet Gráficos no tan comunes
A1: Replicar imágenes
A2: Jerárquicos
B3: Con Fórmula | C3: Sin Fórmula | D3: Con Fórmula | F3: 1. Obtener los datos a partir de la hoja "Datos Introducción"
B4: Tipo | C4: Prod o Serv | D4: Total ventas [$] | F4: 2. Gráfico jerárquico rectángulos
F5: 3. Gráfico jerárquico círculos
A23: Torta
B25: Territorio | C25: PIB
B26: Estados Unidos | C26: 21344667
B27: China | C27: 14216503
B28: Japón | C28: 5176205
A29: Unión Europea | B29: Alemania | C29: 3963880
B30: Reino Unido | C30: 2829163
B31: Francia | C31: 2761633
B32: Otros | C32: 9150456
A41: Radial
C42: Animales
B43: Cualidad | C43: Perro | D43: Gato | E43: Cuy
B44: Ternura | C44: 0.8 | D44: 0.7 | E44: 0.9
B45: Agresividad | C45: 0.6 | D45: 0.8 | E45: 0.3
B46: Independencia | C46: 0.4 | D46: 0.8 | E46: 0.1
B47: Inteligencia | C47: 0.6 | D47: 0.7 | E47: 0.2
B48: Sabor | C48: 0.05 | D48: 0.03 | E48: 0.99
A58: Barras - Gant
A60: Actividad | B60: Fecha ini | C60: Duración
A61: ac1 | B61: 44106 | C61: 5
A62: ac2 | B62: 44109 | C62: 6
A63: ac3 | B63: 44114 | C63: 1
A64: ac4 | B64: 44114 | C64: 18
A65: ac5 | B65: 44119 | C65: 5
A66: ac6 | B66: 44129 | C66: 2
A67: ac7 | B67: 44134 | C67: 6
A68: ac8 | B68: 44134 | C68: 1
A76: Barras - Pirámide
A79: Peso | B79: Gatos | C79: Perros | D79: Perros mod
A80: 50-inf | B80: 0 | C80: 1589451
A81: 45-50 | B81: 0 | C81: 1200541
A82: 40-45 | B82: 1 | C82: 2915105
A83: 35-40 | B83: 216 | C83: 2515201
A84: 30-35 | B84: 7852 | C84: 5604153
A85: 25-30 | B85: 60854 | C85: 6894123
...

Sheet Hoja4
A3: Etiquetas de fila | B3: Suma de Unidades | C3: Promedio de Precio unitario [COP] | D3: Suma de Total | E3: Suma de Campo1 | F3: Suma de ampo
A4: cama | B4: 20 | C4: 400000 | D4: 8000000 | E4: 48000000 | F4: 33.333333
A5: mesa | B5: 12 | C5: 80000 | D5: 960000 | E5: 3840000 | F5: 30
A6: silla | B6: 17 | C6: 15000 | D6: 255000 | E6: 1275000 | F6: 34
A7: Total general | B7: 49 | C7: 186333.33 | D7: 9215000 | E7: 136955000 | F7: 32.666667
A10: Calcular ->Anlaizar datos -> calculos-> calculos, elemetos

Sheet Hoja5
A3: Etiquetas de fila | B3: Suma de Unidades
A4: cama | B4: 20
A5: amarillo | B5: 5
A6: azul | B6: 5
A7: negro | B7: 10
A8: mesa | B8: 12
A9: amarillo | B9: 4
A10: azul | B10: 3
A11: negro | B11: 3
A12: verde | B12: 2
A13: silla | B13: 17
A14: amarillo | B14: 7
A15: azul | B15: 5
... A17: Total general | B17: 49

Sheet Hoja6
B21: Me paro en la tabla con mis datos originales y selecciono -> insertar-> graficos dinamicos

Sheet Practica
A3: Etiquetas de columna
A4: amarillo | B4: azul | C4: negro | D4: verde | E4: Total general

Sheet Dinámicos
A1: Fecha | B1: Producto | C1: Estado | D1: Color | E1: Precio unitario [COP] | F1: Unidades | G1: Total | H1: unos | J1: Insertar -> Tabla dinámica
A2: 43839 | B2: silla | C2: nuevo | D2: verde | E2: 15000 | F2: 2 | G2: =E2*F2 -> 30000 | H2: 1 | J2: Insertar -> Gráfico dinámico | M2: para visualizar -> diseño tabla din-> mostrar
A3: 43847 | B3: silla | C3: usado | D3: amarillo | E3: 15000 | F3: 4 | G3: =E3*F3 -> 60000 | H3: 1 | M3: no se actuliza automaticamente -> entonces click derecho -> actualizar
A4: 43853 | B4: silla | C4: no se sabe | D4: amarillo | E4: 15000 | F4: 3 | G4: =E4*F4 -> 45000 | H4: 1 | J4: INTRODUCCIÓN
A5: 43854 | B5: silla | C5: no se sabe | D5: azul | E5: 15000 | F5: 5 | G5: =E5*F5 -> 75000 | H5: 1 | J5: 1. Crear tabla dinámica.
A6: 43879 | B6: mesa | C6: usado | D6: negro | E6: 80000 | F6: 3 | G6: =E6*F6 -> 240000 | H6: 1 | J6: 2. Filas -> Producto
A7: 43883 | B7: cama | C7: no se sabe | D7: amarillo | E7: 400000 | F7: 2 | G7: =E7*F7 -> 800000 | H7: 1 | J7: 3. Columnas -> Color
A8: 43904 | B8: cama | C8: nuevo | D8: azul | E8: 400000 | F8: 4 | G8: =E8*F8 -> 1600000 | H8: 1 | J8: 4. Valores -> suma de unidades
A9: 43922 | B9: mesa | C9: no se sabe | D9: amarillo | E9: 80000 | F9: 4 | G9: =E9*F9 -> 320000 | H9: 1 | J9: 5. Filtro -> Estado
A10: 43934 | B10: silla | C10: usado | D10: verde | E10: 15000 | F10: 3 | G10: =E10*F10 -> 45000 | H10: 1 | J10: 6. Cambiar un dato en la tabla original y ver el efecto en la tabla dinámica
A11: 43935 | B11: cama | C11: nuevo | D11: azul | E11: 400000 | F11: 1 | G11: =E11*F11 -> 400000 | H11: 1 | J11: 7. Actualizar tabla dinámica
A12: 43948 | B12: mesa | C12: usado | D12: verde | E12: 80000 | F12: 2 | G12: =E12*F12 -> 160000 | H12: 1 | J12: 8. Agrupe las sillas y las mesas
A13: 43972 | B13: cama | C13: usado | D13: negro | E13: 400000 | F13: 5 | G13: =E13*F13 -> 2000000 | H13: 1 | J13: 9. Cambiarle el nombre al grupo (F2)
A14: 43974 | B14: cama | C14: nuevo | D14: amarillo | E14: 400000 | F14: 3 | G14: =E14*F14 -> 1200000 | H14: 1 | J14: 10. Organice los colores de Z -> A.
A15: 44007 | B15: mesa | C15: no se sabe | D15: azul | E15: 80000 | F15: 3 | G15: =E15*F15 -> 240000 | H15: 1
A16: 44010 | B16: cama | C16: usado | D16: negro | E16: 400000 | F16: 5 | G16: =E16*F16 -> 2000000 | H16: 1
J17: TABLAS DINÁMICAS -> Segmentación de datos
J18: 1. Crear tabla dinámica que muestre en filas el producto con su color y en columnas muestre el mes. En valores ponga la suma de unidades
J19: 2. Adicione en valores la cantidad de unidades mostrada como porcentaje de total de filas
J20: 3. Cambie los meses por trimestres
J21: 4. No muestre los productos de color azul, tampoco los productos mesa
J22: 5. Haga un filtro por el Estado de los objetos
J23: 6. Elimine el filtro y realice una segmentación con el estado de los objetos
J24: 7. Ordene las filas en orden descendente por la suma de unidades
J25: 8. Ocultar botones, encabezados y lista de campos
J26: 9. Eliminar subtotales y totales generales
J29: TABLAS DINÁMICAS -> campo calculado
J30: 1. Cree una tabla dinámica. En fila coloque los productos y en valores coloque precio unitario, cantidad de productos y el total de ventas
... J41: 5. Adicione en valores el promedio del precio y muestrelo en un segundo plano vertical

Sheet Hoja1
A1: Estado | B1: (Todas)
A3: Suma de Unidades | B3: Etiquetas de columna
A4: Etiquetas de fila | B4: verde | C4: negro | D4: azul | E4: amarillo | F4: Total general
A5: mesa | B5: 2 | C5: 3 | D5: 3 | E5: 4 | F5: 12 | H5: Click derecho -> Agrupar o desagruoar (jerarquias)
A6: silla | B6: 5 | D6: 5 | E6: 7 | F6: 17
A7: cama | C7: 10 | D7: 5 | E7: 5 | F7: 20
A8: Total general | B8: 7 | C8: 13 | D8: 13 | E8: 16 | F8: 49

Sheet Hoja3
A1: Estado | B1: nuevo
A3: Suma de Unidades | C3: Meses (Fecha)
A4: Producto | B4: Color | C4: ene | D4: mar | E4: abr | F4: may | G4: Total general | J4: Segmentacion de datos -> en una celda-> analizar-> insertar segmentacion
A5: cama | D5: 4 | E5: 1 | F5: 3 | G5: 8 | J5: Diseño -> Subtotales ->
B6: amarillo | F6: 3 | G6: 3
B7: azul | D7: 4 | E7: 1 | G7: 5
A8: silla | C8: 2 | G8: 2
B9: verde | C9: 2 | G9: 2
A10: Total general | C10: 2 | D10: 4 | E10: 1 | F10: 3 | G10: 10
