Workbook
Name Materias: #REF!

Sheet EJERCICIOS
E6: IIND 2109
F7: Complementaria 3: Formulación
B10: Usted es analista del centro control de operaciones (CCO) de una aerolínea Colombiana y como tal debe brindar apoyo sobre la información de los vuelos registrados durante los últimos años. Su jefe le ha solicitado crear una herramienta de apoyo que le permita analizar la información de vuelos de la época de navidad del año 2016 de forma rápida. En las pestañas 18, 19, ... , 25 encontrará la información del itinerario de vuelo (Id del vuelo, Origen, Destino, Hora de salida y Hora de llegada) para el mes de Diciembre de 2016. Tenga en cuenta que la duración de vuelo será la diferencia de la hora de salida y la hora de llegada.
B16: Punto 1
B17: Teniendo en cuenta la información de los vuelos dada en la tabla 1. Realice el código, en la tabla 2, para cada uno de los vuelos que se presentan. El código estará estructurado de la siguiente forma: - La primera parte del código esta conformada por la letra de la mitad de la sigla de la ciudad de salida y la última letra del código de la ciudad de llegada. (Ejemplo: BAQ (salida) y BGA (llegada), la primera parte del código es "AA") - La segunda parte del código es la información del tiempo de vuelo en horas enteras. - La tercera parte del código es el día, el mes y los dos últimos dígitos del año del vuelo. (Ejemplo: 12/09/2018, el código sería: "120918")
C26: Tabla 1. Inicial | I26: Tabla 2. Código
C27: Salida | D27: Llegada | E27: Tiempo (min) | F27: Fecha | G27: No de Vuelos | I27: Código
C28: BAQ | D28: BGA | E28: =RANDBETWEEN(30,75) -> 51 | F28: =RANDBETWEEN(43106,43861) -> 43678 | G28: 3 | I28: =MID(C28,2,1)&RIGHT(D28,1)&ROUND(E28/60,0)&DAY(F28)&IF(MONTH(F28)<10,0&MONTH(F28),MONTH(F28))&RIGHT(YEAR(F28),2) -> AA110819 | J28: {=MID(C28:C41,2,1)&MID(D28:D41,3,1)&MONTH(F28)&"0"&DAY(F28)&YEAR(F28)} -> AA8012019
C29: BGA | D29: SMR | E29: =RANDBETWEEN(30,75) -> 55 | F29: =RANDBETWEEN(43106,43861) -> 43765 | G29: 1 | I29: =MID(C29,2,1)&RIGHT(D29,1)&ROUND(E29/60,0)&DAY(F29)&IF(MONTH(F29)<10,0&MONTH(F29),MONTH(F29))&RIGHT(YEAR(F29),2) -> GR1271019 | J29: GR8012019
C30: SMR | D30: ADZ | E30: =RANDBETWEEN(30,75) -> 67 | F30: =RANDBETWEEN(43106,43861) -> 43321 | G30: 3 | I30: =MID(C30,2,1)&RIGHT(D30,1)&ROUND(E30/60,0)&DAY(F30)&IF(MONTH(F30)<10,0&MONTH(F30),MONTH(F30))&RIGHT(YEAR(F30),2) -> MZ190818 | J30: MZ8012019
C31: ADZ | D31: VUP | E31: =RANDBETWEEN(30,75) -> 42 | F31: =RANDBETWEEN(43106,43861) -> 43446 | G31: 6 | I31: =MID(C31,2,1)&RIGHT(D31,1)&ROUND(E31/60,0)&DAY(F31)&IF(MONTH(F31)<10,0&MONTH(F31),MONTH(F31))&RIGHT(YEAR(F31),2) -> DP1121218 | J31: DP8012019
C32: VUP | D32: CTG | E32: =RANDBETWEEN(30,75) -> 30 | F32: =RANDBETWEEN(43106,43861) -> 43513 | G32: 1 | I32: =MID(C32,2,1)&RIGHT(D32,1)&ROUND(E32/60,0)&DAY(F32)&IF(MONTH(F32)<10,0&MONTH(F32),MONTH(F32))&RIGHT(YEAR(F32),2) -> UG1170219 | J32: UG8012019
C33: CTG | D33: MDE | E33: =RANDBETWEEN(30,75) -> 33 | F33: =RANDBETWEEN(43106,43861) -> 43192 | G33: 7 | I33: =MID(C33,2,1)&RIGHT(D33,1)&ROUND(E33/60,0)&DAY(F33)&IF(MONTH(F33)<10,0&MONTH(F33),MONTH(F33))&RIGHT(YEAR(F33),2) -> TE120418 | J33: TE8012019
C34: MDE | D34: MTR | E34: =RANDBETWEEN(30,75) -> 35 | F34: =RANDBETWEEN(43106,43861) -> 43807 | G34: 6 | I34: =MID(C34,2,1)&RIGHT(D34,1)&ROUND(E34/60,0)&DAY(F34)&IF(MONTH(F34)<10,0&MONTH(F34),MONTH(F34))&RIGHT(YEAR(F34),2) -> DR181219 | J34: DR8012019
C35: MTR | D35: LET | E35: =RANDBETWEEN(30,75) -> 35 | F35: =RANDBETWEEN(43106,43861) -> 43737 | G35: 2 | I35: =MID(C35,2,1)&RIGHT(D35,1)&ROUND(E35/60,0)&DAY(F35)&IF(MONTH(F35)<10,0&MONTH(F35),MONTH(F35))&RIGHT(YEAR(F35),2) -> TT1290919 | J35: TT8012019
C36: LET | D36: PEI | E36: =RANDBETWEEN(30,75) -> 63 | F36: =RANDBETWEEN(43106,43861) -> 43129 | G36: 2 | I36: =MID(C36,2,1)&RIGHT(D36,1)&ROUND(E36/60,0)&DAY(F36)&IF(MONTH(F36)<10,0&MONTH(F36),MONTH(F36))&RIGHT(YEAR(F36),2) -> EI1290118 | J36: EI8012019
C37: PEI | D37: BOG | E37: =RANDBETWEEN(30,75) -> 73 | F37: =RANDBETWEEN(43106,43861) -> 43625 | G37: 1 | I37: =MID(C37,2,1)&RIGHT(D37,1)&ROUND(E37/60,0)&DAY(F37)&IF(MONTH(F37)<10,0&MONTH(F37),MONTH(F37))&RIGHT(YEAR(F37),2) -> EG190619 | J37: EG8012019
C38: BOG | D38: CUC | E38: =RANDBETWEEN(30,75) -> 72 | F38: =RANDBETWEEN(43106,43861) -> 43606 | G38: 28 | I38: =MID(C38,2,1)&RIGHT(D38,1)&ROUND(E38/60,0)&DAY(F38)&IF(MONTH(F38)<10,0&MONTH(F38),MONTH(F38))&RIGHT(YEAR(F38),2) -> OC1210519 | J38: OC8012019
C39: CUC | D39: EYP | E39: =RANDBETWEEN(30,75) -> 30 | F39: =RANDBETWEEN(43106,43861) -> 43631 | G39: 1 | I39: =MID(C39,2,1)&RIGHT(D39,1)&ROUND(E39/60,0)&DAY(F39)&IF(MONTH(F39)<10,0&MONTH(F39),MONTH(F39))&RIGHT(YEAR(F39),2) -> UP1150619 | J39: UP8012019
C40: EYP | D40: CLO | E40: =RANDBETWEEN(30,75) -> 50 | F40: =RANDBETWEEN(43106,43861) -> 43573 | G40: 1 | I40: =MID(C40,2,1)&RIGHT(D40,1)&ROUND(E40/60,0)&DAY(F40)&IF(MONTH(F40)<10,0&MONTH(F40),MONTH(F40))&RIGHT(YEAR(F40),2) -> YO1180419 | J40: YO8012019
C41: CLO | D41: BAQ | E41: =RANDBETWEEN(30,75) -> 39 | F41: =RANDBETWEEN(43106,43861) -> 43159 | G41: 5 | I41: =MID(C41,2,1)&RIGHT(D41,1)&ROUND(E41/60,0)&DAY(F41)&IF(MONTH(F41)<10,0&MONTH(F41),MONTH(F41))&RIGHT(YEAR(F41),2) -> LQ1280218 | J41: LQ8012019
B44: Punto 2
B45: Por medio de una única fórmula retorne el código de la ciudad que entra por parámetro. Además, utilice otra fórmula que le permita retornar el número de vuelos que tiene asociada la ciudad.
C49: Código | D49: Ciudad Origen | E49: # Vuelos
C50: BAQ | D50: Barranquilla | E50: =RANDBETWEEN(1,10) -> 8 | G50: Ciudad | H50: San Andrés
C51: BGA | D51: Bucaramanga | E51: =RANDBETWEEN(1,10) -> 5 | G51: Código | H51: =INDEX(C50:E63,MATCH(H50,D50:D63,0),MATCH(C49,C49:E49,0)) -> ADZ | I51: =INDEX($C$50:$E$63,MATCH($H$50,$D$50:$D$63,0),MATCH($G51,$C$49:$E$49,0)) -> ADZ
C52: SMR | D52: Santa Marta | E52: =RANDBETWEEN(1,10) -> 7 | G52: # vuelos | H52: =INDEX(C50:E63,MATCH(H50,D50:D63,0),MATCH(E49,C49:E49,0)) -> 9 | I52: =INDEX($C$50:$E$63,MATCH($H$50,$D$50:$D$63,0),MATCH($G52,$C$49:$E$49,0)) -> 9
C53: ADZ | D53: San Andrés | E53: =RANDBETWEEN(1,10) -> 9 | H53: =VLOOKUP(H50,D50:E63,2) -> 4
C54: VUP | D54: Valledupar | E54: =RANDBETWEEN(1,10) -> 8
C55: CTG | D55: Cartagena | E55: =RANDBETWEEN(1,10) -> 6
C56: MDE | D56: Medellín | E56: =RANDBETWEEN(1,10) -> 5
C57: MTR | D57: Montería | E57: =RANDBETWEEN(1,10) -> 10
C58: LET | D58: Leticia | E58: =RANDBETWEEN(1,10) -> 8
C59: PEI | D59: Pereira | E59: =RANDBETWEEN(1,10) -> 2
C60: BOG | D60: Bogotá | E60: =RANDBETWEEN(1,10) -> 6
C61: CUC | D61: Cúcuta | E61: =RANDBETWEEN(1,10) -> 4
C62: EYP | D62: Yopal | E62: =RANDBETWEEN(1,10) -> 6
C63: CLO | D63: Cali | E63: =RANDBETWEEN(1,10) -> 8
B66: Punto 3
B67: A partir de una formula, defina el tiempo total en minutos de un vuelo seleccionado para el 25 de Diciembre de 2016.
...

Sheet 18
B2: Flight | C2: Origin | D2: Destination | E2: Departure | F2: Arrival
B3: 3003 | C3: MDE | D3: BOG | E3: 42722.373 | F3: 42722.411
B4: 3004 | C4: BOG | D4: MDE | E4: 42722.364 | F4: 42722.405
B5: 3005 | C5: MDE | D5: BOG | E5: 42722.426 | F5: 42722.464
B6: 3010 | C6: BOG | D6: MDE | E6: 42722.426 | F6: 42722.467
B7: 3016 | C7: BOG | D7: MDE | E7: 42722.52 | F7: 42722.561
B8: 3017 | C8: MDE | D8: BOG | E8: 42722.582 | F8: 42722.62
B9: 3018 | C9: BOG | D9: MDE | E9: 42722.638 | F9: 42722.679
B10: 3025 | C10: MDE | D10: BOG | E10: 42722.731 | F10: 42722.769
B11: 3044 | C11: BOG | D11: ADZ | E11: 42722.368 | F11: 42722.462
B12: 3045 | C12: ADZ | D12: BOG | E12: 42722.517 | F12: 42722.604
B13: 3046 | C13: BOG | D13: ADZ | E13: 42722.645 | F13: 42722.739
B14: 3047 | C14: ADZ | D14: BOG | E14: 42722.767 | F14: 42722.854
... B72: 3313 | C72: CTG | D72: MDE | E72: 42722.726 | F72: 42722.775

Sheet 19
B2: Flight | C2: Origin | D2: Destination | E2: Departure | F2: Arrival
B3: 3000 | C3: BOG | D3: MDE | E3: 42723.239 | F3: 42723.28
B4: 3001 | C4: MDE | D4: BOG | E4: 42723.301 | F4: 42723.339
B5: 3002 | C5: BOG | D5: MDE | E5: 42723.267 | F5: 42723.308
B6: 3003 | C6: MDE | D6: BOG | E6: 42723.264 | F6: 42723.302
B7: 3004 | C7: BOG | D7: MDE | E7: 42723.317 | F7: 42723.358
B8: 3005 | C8: MDE | D8: BOG | E8: 42723.378 | F8: 42723.417
B9: 3006 | C9: BOG | D9: MDE | E9: 42723.392 | F9: 42723.433
B10: 3010 | C10: BOG | D10: MDE | E10: 42723.456 | F10: 42723.497
B11: 3011 | C11: MDE | D11: BOG | E11: 42723.524 | F11: 42723.562
B12: 3013 | C12: MDE | D12: BOG | E12: 42723.681 | F12: 42723.719
B13: 3014 | C13: BOG | D13: MDE | E13: 42723.67 | F13: 42723.711
B14: 3015 | C14: MDE | D14: BOG | E14: 42723.733 | F14: 42723.771
... B126: 3311 | C126: CTG | D126: MDE | E126: 42723.738 | F126: 42723.787

Sheet 20
B2: Flight | C2: Origin | D2: Destination | E2: Departure | F2: Arrival
B3: 3000 | C3: BOG | D3: MDE | E3: 42724.24 | F3: 42724.281
B4: 3001 | C4: MDE | D4: BOG | E4: 42724.306 | F4: 42724.344
B5: 3002 | C5: BOG | D5: MDE | E5: 42724.267 | F5: 42724.308
B6: 3003 | C6: MDE | D6: BOG | E6: 42724.285 | F6: 42724.323
B7: 3004 | C7: BOG | D7: MDE | E7: 42724.317 | F7: 42724.358
B8: 3005 | C8: MDE | D8: BOG | E8: 42724.378 | F8: 42724.417
B9: 3006 | C9: BOG | D9: MDE | E9: 42724.392 | F9: 42724.433
B10: 3010 | C10: BOG | D10: MDE | E10: 42724.539 | F10: 42724.58
B11: 3011 | C11: MDE | D11: BOG | E11: 42724.608 | F11: 42724.646
B12: 3013 | C12: MDE | D12: BOG | E12: 42724.68 | F12: 42724.718
B13: 3014 | C13: BOG | D13: MDE | E13: 42724.667 | F13: 42724.708
B14: 3015 | C14: MDE | D14: BOG | E14: 42724.728 | F14: 42724.767
... B122: 3311 | C122: CTG | D122: MDE | E122: 42724.732 | F122: 42724.781

Sheet 21
B2: Flight | C2: Origin | D2: Destination | E2: Departure | F2: Arrival
B3: 3000 | C3: BOG | D3: MDE | E3: 42725.239 | F3: 42725.28
B4: 3001 | C4: MDE | D4: BOG | E4: 42725.306 | F4: 42725.344
B5: 3002 | C5: BOG | D5: MDE | E5: 42725.267 | F5: 42725.308
B6: 3003 | C6: MDE | D6: BOG | E6: 42725.264 | F6: 42725.302
B7: 3004 | C7: BOG | D7: MDE | E7: 42725.322 | F7: 42725.363
B8: 3005 | C8: MDE | D8: BOG | E8: 42725.378 | F8: 42725.417
B9: 3006 | C9: BOG | D9: MDE | E9: 42725.39 | F9: 42725.431
B10: 3010 | C10: BOG | D10: MDE | E10: 42725.463 | F10: 42725.503
B11: 3011 | C11: MDE | D11: BOG | E11: 42725.524 | F11: 42725.562
B12: 3013 | C12: MDE | D12: BOG | E12: 42725.676 | F12: 42725.714
B13: 3014 | C13: BOG | D13: MDE | E13: 42725.67 | F13: 42725.711
B14: 3015 | C14: MDE | D14: BOG | E14: 42725.732 | F14: 42725.77
... B116: 4162 | C116: BOG | D116: BGA | E116: 42725.333 | F116: 42725.376

Sheet 22
B2: Flight | C2: Origin | D2: Destination | E2: Departure | F2: Arrival
B3: 3000 | C3: BOG | D3: MDE | E3: 42726.239 | F3: 42726.28
B4: 3001 | C4: MDE | D4: BOG | E4: 42726.306 | F4: 42726.344
B5: 3002 | C5: BOG | D5: MDE | E5: 42726.267 | F5: 42726.308
B6: 3003 | C6: MDE | D6: BOG | E6: 42726.267 | F6: 42726.305
B7: 3004 | C7: BOG | D7: MDE | E7: 42726.317 | F7: 42726.358
B8: 3005 | C8: MDE | D8: BOG | E8: 42726.378 | F8: 42726.417
B9: 3006 | C9: BOG | D9: MDE | E9: 42726.39 | F9: 42726.431
B10: 3010 | C10: BOG | D10: MDE | E10: 42726.548 | F10: 42726.589
B11: 3011 | C11: MDE | D11: BOG | E11: 42726.611 | F11: 42726.649
B12: 3013 | C12: MDE | D12: BOG | E12: 42726.679 | F12: 42726.717
B13: 3016 | C13: BOG | D13: MDE | E13: 42726.721 | F13: 42726.762
B14: 3017 | C14: MDE | D14: BOG | E14: 42726.783 | F14: 42726.821
... B118: 3311 | C118: CTG | D118: MDE | E118: 42726.732 | F118: 42726.781

Sheet 23
B2: Flight | C2: Origin | D2: Destination | E2: Departure | F2: Arrival
B3: 3000 | C3: BOG | D3: MDE | E3: 42727.24 | F3: 42727.281
B4: 3001 | C4: MDE | D4: BOG | E4: 42727.301 | F4: 42727.34
B5: 3002 | C5: BOG | D5: MDE | E5: 42727.267 | F5: 42727.308
B6: 3003 | C6: MDE | D6: BOG | E6: 42727.271 | F6: 42727.309
B7: 3006 | C7: BOG | D7: MDE | E7: 42727.392 | F7: 42727.433
B8: 3010 | C8: BOG | D8: MDE | E8: 42727.531 | F8: 42727.572
B9: 3011 | C9: MDE | D9: BOG | E9: 42727.6 | F9: 42727.638
B10: 3013 | C10: MDE | D10: BOG | E10: 42727.679 | F10: 42727.717
B11: 3014 | C11: BOG | D11: MDE | E11: 42727.667 | F11: 42727.708
B12: 3015 | C12: MDE | D12: BOG | E12: 42727.728 | F12: 42727.767
B13: 3016 | C13: BOG | D13: MDE | E13: 42727.722 | F13: 42727.763
B14: 3017 | C14: MDE | D14: BOG | E14: 42727.784 | F14: 42727.822
... B123: 3311 | C123: CTG | D123: MDE | E123: 42727.74 | F123: 42727.788

Sheet 24
B2: Flight | C2: Origin | D2: Destination | E2: Departure | F2: Arrival
B3: 3000 | C3: BOG | D3: MDE | E3: 42728.271 | F3: 42728.312
B4: 3001 | C4: MDE | D4: BOG | E4: 42728.337 | F4: 42728.375
B5: 3002 | C5: BOG | D5: MDE | E5: 42728.295 | F5: 42728.336
B6: 3006 | C6: BOG | D6: MDE | E6: 42728.377 | F6: 42728.418
B7: 3007 | C7: MDE | D7: BOG | E7: 42728.663 | F7: 42728.701
B8: 3010 | C8: BOG | D8: MDE | E8: 42728.469 | F8: 42728.51
B9: 3011 | C9: MDE | D9: BOG | E9: 42728.531 | F9: 42728.569
B10: 3012 | C10: BOG | D10: MDE | E10: 42728.534 | F10: 42728.575
B11: 3013 | C11: MDE | D11: BOG | E11: 42728.603 | F11: 42728.641
B12: 3015 | C12: MDE | D12: BOG | E12: 42728.75 | F12: 42728.788
B13: 3018 | C13: BOG | D13: MDE | E13: 42728.83 | F13: 42728.871
B14: 3019 | C14: MDE | D14: BOG | E14: 42728.892 | F14: 42728.93
... B111: 3313 | C111: CTG | D111: MDE | E111: 42728.681 | F111: 42728.729

Sheet 25
B2: Flight | C2: Origin | D2: Destination | E2: Departure | F2: Arrival | H2: llegada | I2: depature
B3: 3004 | C3: BOG | D3: MDE | E3: 42729.364 | F3: 42729.405 | G3: =HOUR(F3) -> 9 | H3: =F3 -> 42729.405 | I3: =E3 -> 42729.364 | J3: =H3-I3 -> 0.040972222
B4: 3005 | C4: MDE | D4: BOG | E4: 42729.426 | F4: 42729.464 | H4: =HOUR(F4)/60+MINUTE(F4) -> 8.1833333 | I4: =HOUR(E4)/60+MINUTE(E4) -> 13.166667
B5: 3010 | C5: BOG | D5: MDE | E5: 42729.426 | F5: 42729.467 | H5: =HOUR(F5)/60+MINUTE(F5) -> 13.183333 | I5: =HOUR(E5)/60+MINUTE(E5) -> 14.166667
B6: 3016 | C6: BOG | D6: MDE | E6: 42729.515 | F6: 42729.556 | H6: =HOUR(F6)/60+MINUTE(F6) -> 20.216667 | I6: =HOUR(E6)/60+MINUTE(E6) -> 21.2
B7: 3017 | C7: MDE | D7: BOG | E7: 42729.576 | F7: 42729.615
B8: 3018 | C8: BOG | D8: MDE | E8: 42729.638 | F8: 42729.679
B9: 3025 | C9: MDE | D9: BOG | E9: 42729.731 | F9: 42729.769
B10: 3044 | C10: BOG | D10: ADZ | E10: 42729.368 | F10: 42729.462
B11: 3045 | C11: ADZ | D11: BOG | E11: 42729.517 | F11: 42729.604
B12: 3046 | C12: BOG | D12: ADZ | E12: 42729.645 | F12: 42729.739
B13: 3047 | C13: ADZ | D13: BOG | E13: 42729.767 | F13: 42729.854
B14: 3049 | C14: ADZ | D14: BOG | E14: 42729.811 | F14: 42729.898
B15: 3053 | C15: BOG | D15: CLO | E15: 42729.322 | F15: 42729.368
B16: 3054 | C16: CLO | D16: BOG | E16: 42729.705 | F16: 42729.747
B17: 3055 | C17: BOG | D17: CLO | E17: 42729.406 | F17: 42729.452
B18: 3062 | C18: CLO | D18: BOG | E18: 42729.599 | F18: 42729.641
... B69: 3313 | C69: CTG | D69: MDE | E69: 42729.726 | F69: 42729.775
